Workbook

Sheet TABELA DIRETA
B4: TABELA REFERENCIAL DE CUSTO DE MUDANÇAS DIRETAS | O4: Fevereiro/2026
B6: KM de | D6: KM até | F6: VUC | H6: TOCO 3/4 | J6: TOCO | L6: TOCO | N6: TRUCK | P6: CARRETA
F7: 15 m³ | H7: 30 m³ | J7: 45 m³ | L7: 60 m³ | N7: 75 m³ | P7: 90 m³ | R7: Viagem Ida | T7: MARKUP | U7: ='TX E MARKUP'!C17 -> 1.9542701
B8: 0 | D8: 50 | F8: =(LOCAL_EQUIPE!E$21+LOCAL_VEÍCULO!E$57+EMBALAGEM!F$21)*$U$9 -> 3299.6116 | H8: =(LOCAL_EQUIPE!G$21+LOCAL_VEÍCULO!G$57+EMBALAGEM!H$21)*$U$9 -> 6600.029 | J8: =(LOCAL_EQUIPE!I$21+LOCAL_VEÍCULO!I$57+EMBALAGEM!J$21)*$U$9 -> 8284.0086 | L8: =(LOCAL_EQUIPE!K$21+LOCAL_VEÍCULO!K$57+EMBALAGEM!L$21)*$U$9 -> 12066.015 | N8: =(LOCAL_EQUIPE!M$21+LOCAL_VEÍCULO!M$57+EMBALAGEM!N$21)*$U$9 -> 13666.249 | P8: =(LOCAL_EQUIPE!O$21+LOCAL_VEÍCULO!O$57+EMBALAGEM!P$21)*$U$9 -> 18783.277 | R8: 1 | T8: ICMS
B9: 51 | D9: 100 | F9: =(INTER_EQUIPE!E$13+INTER_VEÍCULO!E$33+('HORA PARADA_VEÍCULO'!E$9*$R9)+('CUSTO KM_VEÍCULO'!E$9*$D9)+EMBALAGEM!F$21+ENTREGA!E$4)*$U$7 -> 4930.8748 | H9: =(INTER_EQUIPE!G$13+INTER_VEÍCULO!G$33+('HORA PARADA_VEÍCULO'!G$9*$R9)+('CUSTO KM_VEÍCULO'!G$9*$D9)+EMBALAGEM!H$21+ENTREGA!G$4)*$U$7 -> 8836.8522 | J9: =(INTER_EQUIPE!I$13+INTER_VEÍCULO!I$33+('HORA PARADA_VEÍCULO'!I$9*$R9)+('CUSTO KM_VEÍCULO'!I$9*$D9)+EMBALAGEM!J$21+ENTREGA!I$4)*$U$7 -> 10906.561 | L9: =(INTER_EQUIPE!K$13+INTER_VEÍCULO!K$33+('HORA PARADA_VEÍCULO'!K$9*$R9)+('CUSTO KM_VEÍCULO'!K$9*$D9)+EMBALAGEM!L$21+ENTREGA!K$4)*$U$7 -> 13781.365 | N9: =(INTER_EQUIPE!M$13+INTER_VEÍCULO!M$33+('HORA PARADA_VEÍCULO'!M$9*$R9)+('CUSTO KM_VEÍCULO'!M$9*$D9)+EMBALAGEM!N$21+ENTREGA!M$4)*$U$7 -> 16604.836 | P9: =(INTER_EQUIPE!O$13+INTER_VEÍCULO!O$33+('HORA PARADA_VEÍCULO'!O$9*$R9)+('CUSTO KM_VEÍCULO'!O$9*$D9)+EMBALAGEM!P$21+ENTREGA!O$4)*$U$7 -> 20823.145 | R9: 1 | T9: MARKUP | U9: ='TX E MARKUP'!C16 -> 1.8597731
B10: 101 | D10: 200 | F10: =(INTER_EQUIPE!E$13+INTER_VEÍCULO!E$33+('HORA PARADA_VEÍCULO'!E$9*$R10)+('CUSTO KM_VEÍCULO'!E$9*$D10)+EMBALAGEM!F$21+ENTREGA!E$4)*$U$7 -> 5219.0358 | H10: =(INTER_EQUIPE!G$13+INTER_VEÍCULO!G$33+('HORA PARADA_VEÍCULO'!G$9*$R10)+('CUSTO KM_VEÍCULO'!G$9*$D10)+EMBALAGEM!H$21+ENTREGA!G$4)*$U$7 -> 9146.6237 | J10: =(INTER_EQUIPE!I$13+INTER_VEÍCULO!I$33+('HORA PARADA_VEÍCULO'!I$9*$R10)+('CUSTO KM_VEÍCULO'!I$9*$D10)+EMBALAGEM!J$21+ENTREGA!I$4)*$U$7 -> 11265.518 | L10: =(INTER_EQUIPE!K$13+INTER_VEÍCULO!K$33+('HORA PARADA_VEÍCULO'!K$9*$R10)+('CUSTO KM_VEÍCULO'!K$9*$D10)+EMBALAGEM!L$21+ENTREGA!K$4)*$U$7 -> 14140.322 | N10: =(INTER_EQUIPE!M$13+INTER_VEÍCULO!M$33+('HORA PARADA_VEÍCULO'!M$9*$R10)+('CUSTO KM_VEÍCULO'!M$9*$D10)+EMBALAGEM!N$21+ENTREGA!M$4)*$U$7 -> 17034.208 | P10: =(INTER_EQUIPE!O$13+INTER_VEÍCULO!O$33+('HORA PARADA_VEÍCULO'!O$9*$R10)+('CUSTO KM_VEÍCULO'!O$9*$D10)+EMBALAGEM!P$21+ENTREGA!O$4)*$U$7 -> 21313.619 | R10: 1 | T10: ISS
B11: 201 | D11: 300 | F11: =(INTER_EQUIPE!E$13+INTER_VEÍCULO!E$33+('HORA PARADA_VEÍCULO'!E$9*$R11)+('CUSTO KM_VEÍCULO'!E$9*$D11)+EMBALAGEM!F$21+ENTREGA!E$4)*$U$7 -> 6358.7455 | H11: =(INTER_EQUIPE!G$13+INTER_VEÍCULO!G$33+('HORA PARADA_VEÍCULO'!G$9*$R11)+('CUSTO KM_VEÍCULO'!G$9*$D11)+EMBALAGEM!H$21+ENTREGA!G$4)*$U$7 -> 10411.512 | J11: =(INTER_EQUIPE!I$13+INTER_VEÍCULO!I$33+('HORA PARADA_VEÍCULO'!I$9*$R11)+('CUSTO KM_VEÍCULO'!I$9*$D11)+EMBALAGEM!J$21+ENTREGA!I$4)*$U$7 -> 12517.889 | L11: =(INTER_EQUIPE!K$13+INTER_VEÍCULO!K$33+('HORA PARADA_VEÍCULO'!K$9*$R11)+('CUSTO KM_VEÍCULO'!K$9*$D11)+EMBALAGEM!L$21+ENTREGA!K$4)*$U$7 -> 15392.692 | N11: =(INTER_EQUIPE!M$13+INTER_VEÍCULO!M$33+('HORA PARADA_VEÍCULO'!M$9*$R11)+('CUSTO KM_VEÍCULO'!M$9*$D11)+EMBALAGEM!N$21+ENTREGA!M$4)*$U$7 -> 18608.713 | P11: =(INTER_EQUIPE!O$13+INTER_VEÍCULO!O$33+('HORA PARADA_VEÍCULO'!O$9*$R11)+('CUSTO KM_VEÍCULO'!O$9*$D11)+EMBALAGEM!P$21+ENTREGA!O$4)*$U$7 -> 22964.217 | R11: 2
B12: 301 | D12: 400 | F12: =(INTER_EQUIPE!E$13+INTER_VEÍCULO!E$33+('HORA PARADA_VEÍCULO'!E$9*$R12)+('CUSTO KM_VEÍCULO'!E$9*$D12)+EMBALAGEM!F$21+ENTREGA!E$4)*$U$7 -> 6646.9065 | H12: =(INTER_EQUIPE!G$13+INTER_VEÍCULO!G$33+('HORA PARADA_VEÍCULO'!G$9*$R12)+('CUSTO KM_VEÍCULO'!G$9*$D12)+EMBALAGEM!H$21+ENTREGA!G$4)*$U$7 -> 10721.284 | J12: =(INTER_EQUIPE!I$13+INTER_VEÍCULO!I$33+('HORA PARADA_VEÍCULO'!I$9*$R12)+('CUSTO KM_VEÍCULO'!I$9*$D12)+EMBALAGEM!J$21+ENTREGA!I$4)*$U$7 -> 12876.845 | L12: =(INTER_EQUIPE!K$13+INTER_VEÍCULO!K$33+('HORA PARADA_VEÍCULO'!K$9*$R12)+('CUSTO KM_VEÍCULO'!K$9*$D12)+EMBALAGEM!L$21+ENTREGA!K$4)*$U$7 -> 15751.649 | N12: =(INTER_EQUIPE!M$13+INTER_VEÍCULO!M$33+('HORA PARADA_VEÍCULO'!M$9*$R12)+('CUSTO KM_VEÍCULO'!M$9*$D12)+EMBALAGEM!N$21+ENTREGA!M$4)*$U$7 -> 19038.085 | P12: =(INTER_EQUIPE!O$13+INTER_VEÍCULO!O$33+('HORA PARADA_VEÍCULO'!O$9*$R12)+('CUSTO KM_VEÍCULO'!O$9*$D12)+EMBALAGEM!P$21+ENTREGA!O$4)*$U$7 -> 23454.69 | R12: 2
B13: 401 | D13: 500 | F13: =(INTER_EQUIPE!E$13+INTER_VEÍCULO!E$33+('HORA PARADA_VEÍCULO'!E$9*$R13)+('CUSTO KM_VEÍCULO'!E$9*$D13)+EMBALAGEM!F$21+ENTREGA!E$4)*$U$7 -> 6935.0676 | H13: =(INTER_EQUIPE!G$13+INTER_VEÍCULO!G$33+('HORA PARADA_VEÍCULO'!G$9*$R13)+('CUSTO KM_VEÍCULO'!G$9*$D13)+EMBALAGEM!H$21+ENTREGA!G$4)*$U$7 -> 11031.055 | J13: =(INTER_EQUIPE!I$13+INTER_VEÍCULO!I$33+('HORA PARADA_VEÍCULO'!I$9*$R13)+('CUSTO KM_VEÍCULO'!I$9*$D13)+EMBALAGEM!J$21+ENTREGA!I$4)*$U$7 -> 13235.802 | L13: =(INTER_EQUIPE!K$13+INTER_VEÍCULO!K$33+('HORA PARADA_VEÍCULO'!K$9*$R13)+('CUSTO KM_VEÍCULO'!K$9*$D13)+EMBALAGEM!L$21+ENTREGA!K$4)*$U$7 -> 16110.606 | N13: =(INTER_EQUIPE!M$13+INTER_VEÍCULO!M$33+('HORA PARADA_VEÍCULO'!M$9*$R13)+('CUSTO KM_VEÍCULO'!M$9*$D13)+EMBALAGEM!N$21+ENTREGA!M$4)*$U$7 -> 19467.458 | P13: =(INTER_EQUIPE!O$13+INTER_VEÍCULO!O$33+('HORA PARADA_VEÍCULO'!O$9*$R13)+('CUSTO KM_VEÍCULO'!O$9*$D13)+EMBALAGEM!P$21+ENTREGA!O$4)*$U$7 -> 23945.164 | R13: 2
B14: 501 | D14: 600 | F14: =(INTER_EQUIPE!E$13+INTER_VEÍCULO!E$33+('HORA PARADA_VEÍCULO'!E$9*$R14)+('CUSTO KM_VEÍCULO'!E$9*$D14)+EMBALAGEM!F$21+ENTREGA!E$4)*$U$7 -> 7223.2286 | H14: =(INTER_EQUIPE!G$13+INTER_VEÍCULO!G$33+('HORA PARADA_VEÍCULO'!G$9*$R14)+('CUSTO KM_VEÍCULO'!G$9*$D14)+EMBALAGEM!H$21+ENTREGA!G$4)*$U$7 -> 11340.827 | J14: =(INTER_EQUIPE!I$13+INTER_VEÍCULO!I$33+('HORA PARADA_VEÍCULO'!I$9*$R14)+('CUSTO KM_VEÍCULO'!I$9*$D14)+EMBALAGEM!J$21+ENTREGA!I$4)*$U$7 -> 13594.759 | L14: =(INTER_EQUIPE!K$13+INTER_VEÍCULO!K$33+('HORA PARADA_VEÍCULO'!K$9*$R14)+('CUSTO KM_VEÍCULO'!K$9*$D14)+EMBALAGEM!L$21+ENTREGA!K$4)*$U$7 -> 16469.562 | N14: =(INTER_EQUIPE!M$13+INTER_VEÍCULO!M$33+('HORA PARADA_VEÍCULO'!M$9*$R14)+('CUSTO KM_VEÍCULO'!M$9*$D14)+EMBALAGEM!N$21+ENTREGA!M$4)*$U$7 -> 19896.83 | P14: =(INTER_EQUIPE!O$13+INTER_VEÍCULO!O$33+('HORA PARADA_VEÍCULO'!O$9*$R14)+('CUSTO KM_VEÍCULO'!O$9*$D14)+EMBALAGEM!P$21+ENTREGA!O$4)*$U$7 -> 24435.638 | R14: 2
B15: 601 | D15: 700 | F15: =(INTER_EQUIPE!E$13+INTER_VEÍCULO!E$33+('HORA PARADA_VEÍCULO'!E$9*$R15)+('CUSTO KM_VEÍCULO'!E$9*$D15)+EMBALAGEM!F$21+ENTREGA!E$4)*$U$7 -> 7511.3896 | H15: =(INTER_EQUIPE!G$13+INTER_VEÍCULO!G$33+('HORA PARADA_VEÍCULO'!G$9*$R15)+('CUSTO KM_VEÍCULO'!G$9*$D15)+EMBALAGEM!H$21+ENTREGA!G$4)*$U$7 -> 11650.598 | J15: =(INTER_EQUIPE!I$13+INTER_VEÍCULO!I$33+('HORA PARADA_VEÍCULO'!I$9*$R15)+('CUSTO KM_VEÍCULO'!I$9*$D15)+EMBALAGEM!J$21+ENTREGA!I$4)*$U$7 -> 13953.715 | L15: =(INTER_EQUIPE!K$13+INTER_VEÍCULO!K$33+('HORA PARADA_VEÍCULO'!K$9*$R15)+('CUSTO KM_VEÍCULO'!K$9*$D15)+EMBALAGEM!L$21+ENTREGA!K$4)*$U$7 -> 16828.519 | N15: =(INTER_EQUIPE!M$13+INTER_VEÍCULO!M$33+('HORA PARADA_VEÍCULO'!M$9*$R15)+('CUSTO KM_VEÍCULO'!M$9*$D15)+EMBALAGEM!N$21+ENTREGA!M$4)*$U$7 -> 20326.202 | P15: =(INTER_EQUIPE!O$13+INTER_VEÍCULO!O$33+('HORA PARADA_VEÍCULO'!O$9*$R15)+('CUSTO KM_VEÍCULO'!O$9*$D15)+EMBALAGEM!P$21+ENTREGA!O$4)*$U$7 -> 24926.112 | R15: 2
B16: 701 | D16: 800 | F16: =(INTER_EQUIPE!E$13+INTER_VEÍCULO!E$33+('HORA PARADA_VEÍCULO'!E$9*$R16)+('CUSTO KM_VEÍCULO'!E$9*$D16)+EMBALAGEM!F$21+ENTREGA!E$4)*$U$7 -> 8651.0993 | H16: =(INTER_EQUIPE!G$13+INTER_VEÍCULO!G$33+('HORA PARADA_VEÍCULO'!G$9*$R16)+('CUSTO KM_VEÍCULO'!G$9*$D16)+EMBALAGEM!H$21+ENTREGA!G$4)*$U$7 -> 12915.487 | J16: =(INTER_EQUIPE!I$13+INTER_VEÍCULO!I$33+('HORA PARADA_VEÍCULO'!I$9*$R16)+('CUSTO KM_VEÍCULO'!I$9*$D16)+EMBALAGEM!J$21+ENTREGA!I$4)*$U$7 -> 15206.086 | L16: =(INTER_EQUIPE!K$13+INTER_VEÍCULO!K$33+('HORA PARADA_VEÍCULO'!K$9*$R16)+('CUSTO KM_VEÍCULO'!K$9*$D16)+EMBALAGEM!L$21+ENTREGA!K$4)*$U$7 -> 18080.889 | N16: =(INTER_EQUIPE!M$13+INTER_VEÍCULO!M$33+('HORA PARADA_VEÍCULO'!M$9*$R16)+('CUSTO KM_VEÍCULO'!M$9*$D16)+EMBALAGEM!N$21+ENTREGA!M$4)*$U$7 -> 21900.707 | P16: =(INTER_EQUIPE!O$13+INTER_VEÍCULO!O$33+('HORA PARADA_VEÍCULO'!O$9*$R16)+('CUSTO KM_VEÍCULO'!O$9*$D16)+EMBALAGEM!P$21+ENTREGA!O$4)*$U$7 -> 26576.709 | R16: 3
B17: 801 | D17: 900 | F17: =(INTER_EQUIPE!E$13+INTER_VEÍCULO!E$33+('HORA PARADA_VEÍCULO'!E$9*$R17)+('CUSTO KM_VEÍCULO'!E$9*$D17)+EMBALAGEM!F$21+ENTREGA!E$4)*$U$7 -> 8939.2604 | H17: =(INTER_EQUIPE!G$13+INTER_VEÍCULO!G$33+('HORA PARADA_VEÍCULO'!G$9*$R17)+('CUSTO KM_VEÍCULO'!G$9*$D17)+EMBALAGEM!H$21+ENTREGA!G$4)*$U$7 -> 13225.259 | J17: =(INTER_EQUIPE!I$13+INTER_VEÍCULO!I$33+('HORA PARADA_VEÍCULO'!I$9*$R17)+('CUSTO KM_VEÍCULO'!I$9*$D17)+EMBALAGEM!J$21+ENTREGA!I$4)*$U$7 -> 15565.042 | L17: =(INTER_EQUIPE!K$13+INTER_VEÍCULO!K$33+('HORA PARADA_VEÍCULO'!K$9*$R17)+('CUSTO KM_VEÍCULO'!K$9*$D17)+EMBALAGEM!L$21+ENTREGA!K$4)*$U$7 -> 18439.846 | N17: =(INTER_EQUIPE!M$13+INTER_VEÍCULO!M$33+('HORA PARADA_VEÍCULO'!M$9*$R17)+('CUSTO KM_VEÍCULO'!M$9*$D17)+EMBALAGEM!N$21+ENTREGA!M$4)*$U$7 -> 22330.079 | P17: =(INTER_EQUIPE!O$13+INTER_VEÍCULO!O$33+('HORA PARADA_VEÍCULO'!O$9*$R17)+('CUSTO KM_VEÍCULO'!O$9*$D17)+EMBALAGEM!P$21+ENTREGA!O$4)*$U$7 -> 27067.183 | R17: 3
B18: 901 | D18: 1000 | F18: =(INTER_EQUIPE!E$13+INTER_VEÍCULO!E$33+('HORA PARADA_VEÍCULO'!E$9*$R18)+('CUSTO KM_VEÍCULO'!E$9*$D18)+EMBALAGEM!F$21+ENTREGA!E$4)*$U$7 -> 9227.4214 | H18: =(INTER_EQUIPE!G$13+INTER_VEÍCULO!G$33+('HORA PARADA_VEÍCULO'!G$9*$R18)+('CUSTO KM_VEÍCULO'!G$9*$D18)+EMBALAGEM!H$21+ENTREGA!G$4)*$U$7 -> 13535.03 | J18: =(INTER_EQUIPE!I$13+INTER_VEÍCULO!I$33+('HORA PARADA_VEÍCULO'!I$9*$R18)+('CUSTO KM_VEÍCULO'!I$9*$D18)+EMBALAGEM!J$21+ENTREGA!I$4)*$U$7 -> 15923.999 | L18: =(INTER_EQUIPE!K$13+INTER_VEÍCULO!K$33+('HORA PARADA_VEÍCULO'!K$9*$R18)+('CUSTO KM_VEÍCULO'!K$9*$D18)+EMBALAGEM!L$21+ENTREGA!K$4)*$U$7 -> 18798.803 | N18: =(INTER_EQUIPE!M$13+INTER_VEÍCULO!M$33+('HORA PARADA_VEÍCULO'!M$9*$R18)+('CUSTO KM_VEÍCULO'!M$9*$D18)+EMBALAGEM!N$21+ENTREGA!M$4)*$U$7 -> 22759.452 | P18: =(INTER_EQUIPE!O$13+INTER_VEÍCULO!O$33+('HORA PARADA_VEÍCULO'!O$9*$R18)+('CUSTO KM_VEÍCULO'!O$9*$D18)+EMBALAGEM!P$21+ENTREGA!O$4)*$U$7 -> 27557.657 | R18: 3
B19: 1001 | D19: 1100 | F19: =(INTER_EQUIPE!E$13+INTER_VEÍCULO!E$33+('HORA PARADA_VEÍCULO'!E$9*$R19)+('CUSTO KM_VEÍCULO'!E$9*$D19)+EMBALAGEM!F$21+ENTREGA!E$4)*$U$7 -> 9515.5824 | H19: =(INTER_EQUIPE!G$13+INTER_VEÍCULO!G$33+('HORA PARADA_VEÍCULO'!G$9*$R19)+('CUSTO KM_VEÍCULO'!G$9*$D19)+EMBALAGEM!H$21+ENTREGA!G$4)*$U$7 -> 13844.802 | J19: =(INTER_EQUIPE!I$13+INTER_VEÍCULO!I$33+('HORA PARADA_VEÍCULO'!I$9*$R19)+('CUSTO KM_VEÍCULO'!I$9*$D19)+EMBALAGEM!J$21+ENTREGA!I$4)*$U$7 -> 16282.956 | L19: =(INTER_EQUIPE!K$13+INTER_VEÍCULO!K$33+('HORA PARADA_VEÍCULO'!K$9*$R19)+('CUSTO KM_VEÍCULO'!K$9*$D19)+EMBALAGEM!L$21+ENTREGA!K$4)*$U$7 -> 19157.759 | N19: =(INTER_EQUIPE!M$13+INTER_VEÍCULO!M$33+('HORA PARADA_VEÍCULO'!M$9*$R19)+('CUSTO KM_VEÍCULO'!M$9*$D19)+EMBALAGEM!N$21+ENTREGA!M$4)*$U$7 -> 23188.824 | P19: =(INTER_EQUIPE!O$13+INTER_VEÍCULO!O$33+('HORA PARADA_VEÍCULO'!O$9*$R19)+('CUSTO KM_VEÍCULO'!O$9*$D19)+EMBALAGEM!P$21+ENTREGA!O$4)*$U$7 -> 28048.131 | R19: 3
B20: 1101 | D20: 1200 | F20: =(INTER_EQUIPE!E$13+INTER_VEÍCULO!E$33+('HORA PARADA_VEÍCULO'!E$9*$R20)+('CUSTO KM_VEÍCULO'!E$9*$D20)+EMBALAGEM!F$21+ENTREGA!E$4)*$U$7 -> 9803.7435 | H20: =(INTER_EQUIPE!G$13+INTER_VEÍCULO!G$33+('HORA PARADA_VEÍCULO'!G$9*$R20)+('CUSTO KM_VEÍCULO'!G$9*$D20)+EMBALAGEM!H$21+ENTREGA!G$4)*$U$7 -> 14154.573 | J20: =(INTER_EQUIPE!I$13+INTER_VEÍCULO!I$33+('HORA PARADA_VEÍCULO'!I$9*$R20)+('CUSTO KM_VEÍCULO'!I$9*$D20)+EMBALAGEM!J$21+ENTREGA!I$4)*$U$7 -> 16641.912 | L20: =(INTER_EQUIPE!K$13+INTER_VEÍCULO!K$33+('HORA PARADA_VEÍCULO'!K$9*$R20)+('CUSTO KM_VEÍCULO'!K$9*$D20)+EMBALAGEM!L$21+ENTREGA!K$4)*$U$7 -> 19516.716 | N20: =(INTER_EQUIPE!M$13+INTER_VEÍCULO!M$33+('HORA PARADA_VEÍCULO'!M$9*$R20)+('CUSTO KM_VEÍCULO'!M$9*$D20)+EMBALAGEM!N$21+ENTREGA!M$4)*$U$7 -> 23618.196 | P20: =(INTER_EQUIPE!O$13+INTER_VEÍCULO!O$33+('HORA PARADA_VEÍCULO'!O$9*$R20)+('CUSTO KM_VEÍCULO'!O$9*$D20)+EMBALAGEM!P$21+ENTREGA!O$4)*$U$7 -> 28538.605 | R20: 3
B21: 1201 | D21: 1300 | F21: =(INTER_EQUIPE!E$13+INTER_VEÍCULO!E$33+('HORA PARADA_VEÍCULO'!E$9*$R21)+('CUSTO KM_VEÍCULO'!E$9*$D21)+EMBALAGEM!F$21+ENTREGA!E$4)*$U$7 -> 10943.453 | H21: =(INTER_EQUIPE!G$13+INTER_VEÍCULO!G$33+('HORA PARADA_VEÍCULO'!G$9*$R21)+('CUSTO KM_VEÍCULO'!G$9*$D21)+EMBALAGEM!H$21+ENTREGA!G$4)*$U$7 -> 15419.462 | J21: =(INTER_EQUIPE!I$13+INTER_VEÍCULO!I$33+('HORA PARADA_VEÍCULO'!I$9*$R21)+('CUSTO KM_VEÍCULO'!I$9*$D21)+EMBALAGEM!J$21+ENTREGA!I$4)*$U$7 -> 17894.283 | L21: =(INTER_EQUIPE!K$13+INTER_VEÍCULO!K$33+('HORA PARADA_VEÍCULO'!K$9*$R21)+('CUSTO KM_VEÍCULO'!K$9*$D21)+EMBALAGEM!L$21+ENTREGA!K$4)*$U$7 -> 20769.087 | N21: =(INTER_EQUIPE!M$13+INTER_VEÍCULO!M$33+('HORA PARADA_VEÍCULO'!M$9*$R21)+('CUSTO KM_VEÍCULO'!M$9*$D21)+EMBALAGEM!N$21+ENTREGA!M$4)*$U$7 -> 25192.701 | P21: =(INTER_EQUIPE!O$13+INTER_VEÍCULO!O$33+('HORA PARADA_VEÍCULO'!O$9*$R21)+('CUSTO KM_VEÍCULO'!O$9*$D21)+EMBALAGEM!P$21+ENTREGA!O$4)*$U$7 -> 30189.202 | R21: 4
B22: 1301 | D22: 1400 | F22: =(INTER_EQUIPE!E$13+INTER_VEÍCULO!E$33+('HORA PARADA_VEÍCULO'!E$9*$R22)+('CUSTO KM_VEÍCULO'!E$9*$D22)+EMBALAGEM!F$21+ENTREGA!E$4)*$U$7 -> 11231.614 | H22: =(INTER_EQUIPE!G$13+INTER_VEÍCULO!G$33+('HORA PARADA_VEÍCULO'!G$9*$R22)+('CUSTO KM_VEÍCULO'!G$9*$D22)+EMBALAGEM!H$21+ENTREGA!G$4)*$U$7 -> 15729.233 | J22: =(INTER_EQUIPE!I$13+INTER_VEÍCULO!I$33+('HORA PARADA_VEÍCULO'!I$9*$R22)+('CUSTO KM_VEÍCULO'!I$9*$D22)+EMBALAGEM!J$21+ENTREGA!I$4)*$U$7 -> 18253.239 | L22: =(INTER_EQUIPE!K$13+INTER_VEÍCULO!K$33+('HORA PARADA_VEÍCULO'!K$9*$R22)+('CUSTO KM_VEÍCULO'!K$9*$D22)+EMBALAGEM!L$21+ENTREGA!K$4)*$U$7 -> 21128.043 | N22: =(INTER_EQUIPE!M$13+INTER_VEÍCULO!M$33+('HORA PARADA_VEÍCULO'!M$9*$R22)+('CUSTO KM_VEÍCULO'!M$9*$D22)+EMBALAGEM!N$21+ENTREGA!M$4)*$U$7 -> 25622.073 | P22: =(INTER_EQUIPE!O$13+INTER_VEÍCULO!O$33+('HORA PARADA_VEÍCULO'!O$9*$R22)+('CUSTO KM_VEÍCULO'!O$9*$D22)+EMBALAGEM!P$21+ENTREGA!O$4)*$U$7 -> 30679.676 | R22: 4
... B38: 3801 | D38: 4000 | F38: =(INTER_EQUIPE!E$13+INTER_VEÍCULO!E$33+('HORA PARADA_VEÍCULO'!E$9*$R38)+('CUSTO KM_VEÍCULO'!E$9*$D38)+EMBALAGEM!F$21+ENTREGA!E$4)*$U$7 -> 22129.996 | H38: =(INTER_EQUIPE!G$13+INTER_VEÍCULO!G$33+('HORA PARADA_VEÍCULO'!G$9*$R38)+('CUSTO KM_VEÍCULO'!G$9*$D38)+EMBALAGEM!H$21+ENTREGA!G$4)*$U$7 -> 27603.761 | J38: =(INTER_EQUIPE!I$13+INTER_VEÍCULO!I$33+('HORA PARADA_VEÍCULO'!I$9*$R38)+('CUSTO KM_VEÍCULO'!I$9*$D38)+EMBALAGEM!J$21+ENTREGA!I$4)*$U$7 -> 31159.768 | L38: =(INTER_EQUIPE!K$13+INTER_VEÍCULO!K$33+('HORA PARADA_VEÍCULO'!K$9*$R38)+('CUSTO KM_VEÍCULO'!K$9*$D38)+EMBALAGEM!L$21+ENTREGA!K$4)*$U$7 -> 34034.572 | N38: =(INTER_EQUIPE!M$13+INTER_VEÍCULO!M$33+('HORA PARADA_VEÍCULO'!M$9*$R38)+('CUSTO KM_VEÍCULO'!M$9*$D38)+EMBALAGEM!N$21+ENTREGA!M$4)*$U$7 -> 41366.282 | P38: =(INTER_EQUIPE!O$13+INTER_VEÍCULO!O$33+('HORA PARADA_VEÍCULO'!O$9*$R38)+('CUSTO KM_VEÍCULO'!O$9*$D38)+EMBALAGEM!P$21+ENTREGA!O$4)*$U$7 -> 48072.49 | R38: 8

Sheet TABELA APROVEITAMENTO
B4: MUDANÇAS DE APROVEITAMENTO | G4: Fevereiro/2026
B6: KM de | D6: KM até | F6: ATÉ | H6: ATÉ
F7: 15 m³ | H7: 30 m³ | J7: Viagem Ida | L7: MARKUP | M7: ='TX E MARKUP'!C17 -> 1.9542701
B8: 0 | D8: 50 | F8: 0.25 | H8: 0.4 | J8: ='TABELA DIRETA'!R8 -> 1 | L8: ICMS
B9: 51 | D9: 100 | F9: - | H9: - | I9: =(INTER_EQUIPE!H$13+INTER_VEÍCULO!H$33+(($J9*'HORA PARADA_VEÍCULO'!N$9)+($D9*'CUSTO KM_VEÍCULO'!N$9)*I$8)+'HORA PARADA_VEÍCULO'!$K$9+EMBALAGEM!I$21+ENTREGA!H$4)*$M$7 -> 893.4139 | J9: ='TABELA DIRETA'!R9 -> 1
B10: 101 | D10: 200 | F10: - | G10: =(INTER_EQUIPE!F$13+INTER_VEÍCULO!F$33+((($J10*'HORA PARADA_VEÍCULO'!$K$9)+($D10*'CUSTO KM_VEÍCULO'!$K$9))*G$8)+'HORA PARADA_VEÍCULO'!$K$9+EMBALAGEM!G$21+ENTREGA!F$4)*$M$7 -> 893.4139 | H10: - | I10: =(INTER_EQUIPE!H$13+INTER_VEÍCULO!H$33+(($J10*'HORA PARADA_VEÍCULO'!N$9)+($D10*'CUSTO KM_VEÍCULO'!N$9)*I$8)+'HORA PARADA_VEÍCULO'!$K$9+EMBALAGEM!I$21+ENTREGA!H$4)*$M$7 -> 893.4139 | J10: ='TABELA DIRETA'!R10 -> 1
B11: 201 | D11: 300 | F11: =(INTER_EQUIPE!E$13+INTER_VEÍCULO!E$33+((($J11*'HORA PARADA_VEÍCULO'!$K$9)+($D11*'CUSTO KM_VEÍCULO'!$K$9))*F$8)+'HORA PARADA_VEÍCULO'!$K$9+EMBALAGEM!F$21+ENTREGA!E$4)*$M$7 -> 5400.5034 | G11: =(INTER_EQUIPE!F$13+INTER_VEÍCULO!F$33+((($J11*'HORA PARADA_VEÍCULO'!$K$9)+($D11*'CUSTO KM_VEÍCULO'!$K$9))*G$8)+'HORA PARADA_VEÍCULO'!$K$9+EMBALAGEM!G$21+ENTREGA!F$4)*$M$7 -> 893.4139 | H11: =(INTER_EQUIPE!G$13+INTER_VEÍCULO!G$33+((($J11*'HORA PARADA_VEÍCULO'!$K$9)+($D11*'CUSTO KM_VEÍCULO'!$K$9))*H$8)+'HORA PARADA_VEÍCULO'!$K$9+EMBALAGEM!H$21+ENTREGA!G$4)*$M$7 -> 9610.8564 | I11: =(INTER_EQUIPE!H$13+INTER_VEÍCULO!H$33+(($J11*'HORA PARADA_VEÍCULO'!N$9)+($D11*'CUSTO KM_VEÍCULO'!N$9)*I$8)+'HORA PARADA_VEÍCULO'!$K$9+EMBALAGEM!I$21+ENTREGA!H$4)*$M$7 -> 893.4139 | J11: ='TABELA DIRETA'!R11 -> 2
B12: 301 | D12: 400 | F12: =(INTER_EQUIPE!E$13+INTER_VEÍCULO!E$33+((($J12*'HORA PARADA_VEÍCULO'!$K$9)+($D12*'CUSTO KM_VEÍCULO'!$K$9))*F$8)+'HORA PARADA_VEÍCULO'!$K$9+EMBALAGEM!F$21+ENTREGA!E$4)*$M$7 -> 5490.2426 | G12: =(INTER_EQUIPE!F$13+INTER_VEÍCULO!F$33+((($J12*'HORA PARADA_VEÍCULO'!$K$9)+($D12*'CUSTO KM_VEÍCULO'!$K$9))*G$8)+'HORA PARADA_VEÍCULO'!$K$9+EMBALAGEM!G$21+ENTREGA!F$4)*$M$7 -> 893.4139 | H12: =(INTER_EQUIPE!G$13+INTER_VEÍCULO!G$33+((($J12*'HORA PARADA_VEÍCULO'!$K$9)+($D12*'CUSTO KM_VEÍCULO'!$K$9))*H$8)+'HORA PARADA_VEÍCULO'!$K$9+EMBALAGEM!H$21+ENTREGA!G$4)*$M$7 -> 9754.439 | I12: =(INTER_EQUIPE!H$13+INTER_VEÍCULO!H$33+(($J12*'HORA PARADA_VEÍCULO'!N$9)+($D12*'CUSTO KM_VEÍCULO'!N$9)*I$8)+'HORA PARADA_VEÍCULO'!$K$9+EMBALAGEM!I$21+ENTREGA!H$4)*$M$7 -> 893.4139 | J12: ='TABELA DIRETA'!R12 -> 2
B13: 401 | D13: 500 | F13: =(INTER_EQUIPE!E$13+INTER_VEÍCULO!E$33+((($J13*'HORA PARADA_VEÍCULO'!$K$9)+($D13*'CUSTO KM_VEÍCULO'!$K$9))*F$8)+'HORA PARADA_VEÍCULO'!$K$9+EMBALAGEM!F$21+ENTREGA!E$4)*$M$7 -> 5579.9818 | G13: =(INTER_EQUIPE!F$13+INTER_VEÍCULO!F$33+((($J13*'HORA PARADA_VEÍCULO'!$K$9)+($D13*'CUSTO KM_VEÍCULO'!$K$9))*G$8)+'HORA PARADA_VEÍCULO'!$K$9+EMBALAGEM!G$21+ENTREGA!F$4)*$M$7 -> 893.4139 | H13: =(INTER_EQUIPE!G$13+INTER_VEÍCULO!G$33+((($J13*'HORA PARADA_VEÍCULO'!$K$9)+($D13*'CUSTO KM_VEÍCULO'!$K$9))*H$8)+'HORA PARADA_VEÍCULO'!$K$9+EMBALAGEM!H$21+ENTREGA!G$4)*$M$7 -> 9898.0217 | I13: =(INTER_EQUIPE!H$13+INTER_VEÍCULO!H$33+(($J13*'HORA PARADA_VEÍCULO'!N$9)+($D13*'CUSTO KM_VEÍCULO'!N$9)*I$8)+'HORA PARADA_VEÍCULO'!$K$9+EMBALAGEM!I$21+ENTREGA!H$4)*$M$7 -> 893.4139 | J13: ='TABELA DIRETA'!R13 -> 2
B14: 501 | D14: 600 | F14: =(INTER_EQUIPE!E$13+INTER_VEÍCULO!E$33+((($J14*'HORA PARADA_VEÍCULO'!$K$9)+($D14*'CUSTO KM_VEÍCULO'!$K$9))*F$8)+'HORA PARADA_VEÍCULO'!$K$9+EMBALAGEM!F$21+ENTREGA!E$4)*$M$7 -> 5669.7209 | G14: =(INTER_EQUIPE!F$13+INTER_VEÍCULO!F$33+((($J14*'HORA PARADA_VEÍCULO'!$K$9)+($D14*'CUSTO KM_VEÍCULO'!$K$9))*G$8)+'HORA PARADA_VEÍCULO'!$K$9+EMBALAGEM!G$21+ENTREGA!F$4)*$M$7 -> 893.4139 | H14: =(INTER_EQUIPE!G$13+INTER_VEÍCULO!G$33+((($J14*'HORA PARADA_VEÍCULO'!$K$9)+($D14*'CUSTO KM_VEÍCULO'!$K$9))*H$8)+'HORA PARADA_VEÍCULO'!$K$9+EMBALAGEM!H$21+ENTREGA!G$4)*$M$7 -> 10041.604 | I14: =(INTER_EQUIPE!H$13+INTER_VEÍCULO!H$33+(($J14*'HORA PARADA_VEÍCULO'!N$9)+($D14*'CUSTO KM_VEÍCULO'!N$9)*I$8)+'HORA PARADA_VEÍCULO'!$K$9+EMBALAGEM!I$21+ENTREGA!H$4)*$M$7 -> 893.4139 | J14: ='TABELA DIRETA'!R14 -> 2
B15: 601 | D15: 700 | F15: =(INTER_EQUIPE!E$13+INTER_VEÍCULO!E$33+((($J15*'HORA PARADA_VEÍCULO'!$K$9)+($D15*'CUSTO KM_VEÍCULO'!$K$9))*F$8)+'HORA PARADA_VEÍCULO'!$K$9+EMBALAGEM!F$21+ENTREGA!E$4)*$M$7 -> 5759.4601 | G15: =(INTER_EQUIPE!F$13+INTER_VEÍCULO!F$33+((($J15*'HORA PARADA_VEÍCULO'!$K$9)+($D15*'CUSTO KM_VEÍCULO'!$K$9))*G$8)+'HORA PARADA_VEÍCULO'!$K$9+EMBALAGEM!G$21+ENTREGA!F$4)*$M$7 -> 893.4139 | H15: =(INTER_EQUIPE!G$13+INTER_VEÍCULO!G$33+((($J15*'HORA PARADA_VEÍCULO'!$K$9)+($D15*'CUSTO KM_VEÍCULO'!$K$9))*H$8)+'HORA PARADA_VEÍCULO'!$K$9+EMBALAGEM!H$21+ENTREGA!G$4)*$M$7 -> 10185.187 | I15: =(INTER_EQUIPE!H$13+INTER_VEÍCULO!H$33+(($J15*'HORA PARADA_VEÍCULO'!N$9)+($D15*'CUSTO KM_VEÍCULO'!N$9)*I$8)+'HORA PARADA_VEÍCULO'!$K$9+EMBALAGEM!I$21+ENTREGA!H$4)*$M$7 -> 893.4139 | J15: ='TABELA DIRETA'!R15 -> 2
B16: 701 | D16: 800 | F16: =(INTER_EQUIPE!E$13+INTER_VEÍCULO!E$33+((($J16*'HORA PARADA_VEÍCULO'!$K$9)+($D16*'CUSTO KM_VEÍCULO'!$K$9))*F$8)+'HORA PARADA_VEÍCULO'!$K$9+EMBALAGEM!F$21+ENTREGA!E$4)*$M$7 -> 6072.5527 | G16: =(INTER_EQUIPE!F$13+INTER_VEÍCULO!F$33+((($J16*'HORA PARADA_VEÍCULO'!$K$9)+($D16*'CUSTO KM_VEÍCULO'!$K$9))*G$8)+'HORA PARADA_VEÍCULO'!$K$9+EMBALAGEM!G$21+ENTREGA!F$4)*$M$7 -> 893.4139 | H16: =(INTER_EQUIPE!G$13+INTER_VEÍCULO!G$33+((($J16*'HORA PARADA_VEÍCULO'!$K$9)+($D16*'CUSTO KM_VEÍCULO'!$K$9))*H$8)+'HORA PARADA_VEÍCULO'!$K$9+EMBALAGEM!H$21+ENTREGA!G$4)*$M$7 -> 10686.135 | I16: =(INTER_EQUIPE!H$13+INTER_VEÍCULO!H$33+(($J16*'HORA PARADA_VEÍCULO'!N$9)+($D16*'CUSTO KM_VEÍCULO'!N$9)*I$8)+'HORA PARADA_VEÍCULO'!$K$9+EMBALAGEM!I$21+ENTREGA!H$4)*$M$7 -> 893.4139 | J16: ='TABELA DIRETA'!R16 -> 3
B17: 801 | D17: 900 | F17: =(INTER_EQUIPE!E$13+INTER_VEÍCULO!E$33+((($J17*'HORA PARADA_VEÍCULO'!$K$9)+($D17*'CUSTO KM_VEÍCULO'!$K$9))*F$8)+'HORA PARADA_VEÍCULO'!$K$9+EMBALAGEM!F$21+ENTREGA!E$4)*$M$7 -> 6162.2919 | G17: =(INTER_EQUIPE!F$13+INTER_VEÍCULO!F$33+((($J17*'HORA PARADA_VEÍCULO'!$K$9)+($D17*'CUSTO KM_VEÍCULO'!$K$9))*G$8)+'HORA PARADA_VEÍCULO'!$K$9+EMBALAGEM!G$21+ENTREGA!F$4)*$M$7 -> 893.4139 | H17: =(INTER_EQUIPE!G$13+INTER_VEÍCULO!G$33+((($J17*'HORA PARADA_VEÍCULO'!$K$9)+($D17*'CUSTO KM_VEÍCULO'!$K$9))*H$8)+'HORA PARADA_VEÍCULO'!$K$9+EMBALAGEM!H$21+ENTREGA!G$4)*$M$7 -> 10829.718 | I17: =(INTER_EQUIPE!H$13+INTER_VEÍCULO!H$33+(($J17*'HORA PARADA_VEÍCULO'!N$9)+($D17*'CUSTO KM_VEÍCULO'!N$9)*I$8)+'HORA PARADA_VEÍCULO'!$K$9+EMBALAGEM!I$21+ENTREGA!H$4)*$M$7 -> 893.4139 | J17: ='TABELA DIRETA'!R17 -> 3
B18: 901 | D18: 1000 | F18: =(INTER_EQUIPE!E$13+INTER_VEÍCULO!E$33+((($J18*'HORA PARADA_VEÍCULO'!$K$9)+($D18*'CUSTO KM_VEÍCULO'!$K$9))*F$8)+'HORA PARADA_VEÍCULO'!$K$9+EMBALAGEM!F$21+ENTREGA!E$4)*$M$7 -> 6252.031 | G18: =(INTER_EQUIPE!F$13+INTER_VEÍCULO!F$33+((($J18*'HORA PARADA_VEÍCULO'!$K$9)+($D18*'CUSTO KM_VEÍCULO'!$K$9))*G$8)+'HORA PARADA_VEÍCULO'!$K$9+EMBALAGEM!G$21+ENTREGA!F$4)*$M$7 -> 893.4139 | H18: =(INTER_EQUIPE!G$13+INTER_VEÍCULO!G$33+((($J18*'HORA PARADA_VEÍCULO'!$K$9)+($D18*'CUSTO KM_VEÍCULO'!$K$9))*H$8)+'HORA PARADA_VEÍCULO'!$K$9+EMBALAGEM!H$21+ENTREGA!G$4)*$M$7 -> 10973.301 | I18: =(INTER_EQUIPE!H$13+INTER_VEÍCULO!H$33+(($J18*'HORA PARADA_VEÍCULO'!N$9)+($D18*'CUSTO KM_VEÍCULO'!N$9)*I$8)+'HORA PARADA_VEÍCULO'!$K$9+EMBALAGEM!I$21+ENTREGA!H$4)*$M$7 -> 893.4139 | J18: ='TABELA DIRETA'!R18 -> 3
B19: 1001 | D19: 1100 | F19: =(INTER_EQUIPE!E$13+INTER_VEÍCULO!E$33+((($J19*'HORA PARADA_VEÍCULO'!$K$9)+($D19*'CUSTO KM_VEÍCULO'!$K$9))*F$8)+'HORA PARADA_VEÍCULO'!$K$9+EMBALAGEM!F$21+ENTREGA!E$4)*$M$7 -> 6341.7702 | G19: =(INTER_EQUIPE!F$13+INTER_VEÍCULO!F$33+((($J19*'HORA PARADA_VEÍCULO'!$K$9)+($D19*'CUSTO KM_VEÍCULO'!$K$9))*G$8)+'HORA PARADA_VEÍCULO'!$K$9+EMBALAGEM!G$21+ENTREGA!F$4)*$M$7 -> 893.4139 | H19: =(INTER_EQUIPE!G$13+INTER_VEÍCULO!G$33+((($J19*'HORA PARADA_VEÍCULO'!$K$9)+($D19*'CUSTO KM_VEÍCULO'!$K$9))*H$8)+'HORA PARADA_VEÍCULO'!$K$9+EMBALAGEM!H$21+ENTREGA!G$4)*$M$7 -> 11116.883 | I19: =(INTER_EQUIPE!H$13+INTER_VEÍCULO!H$33+(($J19*'HORA PARADA_VEÍCULO'!N$9)+($D19*'CUSTO KM_VEÍCULO'!N$9)*I$8)+'HORA PARADA_VEÍCULO'!$K$9+EMBALAGEM!I$21+ENTREGA!H$4)*$M$7 -> 893.4139 | J19: ='TABELA DIRETA'!R19 -> 3
B20: 1101 | D20: 1200 | F20: =(INTER_EQUIPE!E$13+INTER_VEÍCULO!E$33+((($J20*'HORA PARADA_VEÍCULO'!$K$9)+($D20*'CUSTO KM_VEÍCULO'!$K$9))*F$8)+'HORA PARADA_VEÍCULO'!$K$9+EMBALAGEM!F$21+ENTREGA!E$4)*$M$7 -> 6431.5094 | G20: =(INTER_EQUIPE!F$13+INTER_VEÍCULO!F$33+((($J20*'HORA PARADA_VEÍCULO'!$K$9)+($D20*'CUSTO KM_VEÍCULO'!$K$9))*G$8)+'HORA PARADA_VEÍCULO'!$K$9+EMBALAGEM!G$21+ENTREGA!F$4)*$M$7 -> 893.4139 | H20: =(INTER_EQUIPE!G$13+INTER_VEÍCULO!G$33+((($J20*'HORA PARADA_VEÍCULO'!$K$9)+($D20*'CUSTO KM_VEÍCULO'!$K$9))*H$8)+'HORA PARADA_VEÍCULO'!$K$9+EMBALAGEM!H$21+ENTREGA!G$4)*$M$7 -> 11260.466 | I20: =(INTER_EQUIPE!H$13+INTER_VEÍCULO!H$33+(($J20*'HORA PARADA_VEÍCULO'!N$9)+($D20*'CUSTO KM_VEÍCULO'!N$9)*I$8)+'HORA PARADA_VEÍCULO'!$K$9+EMBALAGEM!I$21+ENTREGA!H$4)*$M$7 -> 893.4139 | J20: ='TABELA DIRETA'!R20 -> 3
B21: 1201 | D21: 1300 | F21: =(INTER_EQUIPE!E$13+INTER_VEÍCULO!E$33+((($J21*'HORA PARADA_VEÍCULO'!$K$9)+($D21*'CUSTO KM_VEÍCULO'!$K$9))*F$8)+'HORA PARADA_VEÍCULO'!$K$9+EMBALAGEM!F$21+ENTREGA!E$4)*$M$7 -> 6744.602 | G21: =(INTER_EQUIPE!F$13+INTER_VEÍCULO!F$33+((($J21*'HORA PARADA_VEÍCULO'!$K$9)+($D21*'CUSTO KM_VEÍCULO'!$K$9))*G$8)+'HORA PARADA_VEÍCULO'!$K$9+EMBALAGEM!G$21+ENTREGA!F$4)*$M$7 -> 893.4139 | H21: =(INTER_EQUIPE!G$13+INTER_VEÍCULO!G$33+((($J21*'HORA PARADA_VEÍCULO'!$K$9)+($D21*'CUSTO KM_VEÍCULO'!$K$9))*H$8)+'HORA PARADA_VEÍCULO'!$K$9+EMBALAGEM!H$21+ENTREGA!G$4)*$M$7 -> 11761.414 | I21: =(INTER_EQUIPE!H$13+INTER_VEÍCULO!H$33+(($J21*'HORA PARADA_VEÍCULO'!N$9)+($D21*'CUSTO KM_VEÍCULO'!N$9)*I$8)+'HORA PARADA_VEÍCULO'!$K$9+EMBALAGEM!I$21+ENTREGA!H$4)*$M$7 -> 893.4139 | J21: ='TABELA DIRETA'!R21 -> 4
B22: 1301 | D22: 1400 | F22: =(INTER_EQUIPE!E$13+INTER_VEÍCULO!E$33+((($J22*'HORA PARADA_VEÍCULO'!$K$9)+($D22*'CUSTO KM_VEÍCULO'!$K$9))*F$8)+'HORA PARADA_VEÍCULO'!$K$9+EMBALAGEM!F$21+ENTREGA!E$4)*$M$7 -> 6834.3411 | G22: =(INTER_EQUIPE!F$13+INTER_VEÍCULO!F$33+((($J22*'HORA PARADA_VEÍCULO'!$K$9)+($D22*'CUSTO KM_VEÍCULO'!$K$9))*G$8)+'HORA PARADA_VEÍCULO'!$K$9+EMBALAGEM!G$21+ENTREGA!F$4)*$M$7 -> 893.4139 | H22: =(INTER_EQUIPE!G$13+INTER_VEÍCULO!G$33+((($J22*'HORA PARADA_VEÍCULO'!$K$9)+($D22*'CUSTO KM_VEÍCULO'!$K$9))*H$8)+'HORA PARADA_VEÍCULO'!$K$9+EMBALAGEM!H$21+ENTREGA!G$4)*$M$7 -> 11904.997 | I22: =(INTER_EQUIPE!H$13+INTER_VEÍCULO!H$33+(($J22*'HORA PARADA_VEÍCULO'!N$9)+($D22*'CUSTO KM_VEÍCULO'!N$9)*I$8)+'HORA PARADA_VEÍCULO'!$K$9+EMBALAGEM!I$21+ENTREGA!H$4)*$M$7 -> 893.4139 | J22: ='TABELA DIRETA'!R22 -> 4
... B38: 3801 | D38: 4000 | F38: =(INTER_EQUIPE!E$13+INTER_VEÍCULO!E$33+((($J38*'HORA PARADA_VEÍCULO'!$K$9)+($D38*'CUSTO KM_VEÍCULO'!$K$9))*F$8)+'HORA PARADA_VEÍCULO'!$K$9+EMBALAGEM!F$21+ENTREGA!E$4)*$M$7 -> 10060.973 | G38: =(INTER_EQUIPE!F$13+INTER_VEÍCULO!F$33+((($J38*'HORA PARADA_VEÍCULO'!$K$9)+($D38*'CUSTO KM_VEÍCULO'!$K$9))*G$8)+'HORA PARADA_VEÍCULO'!$K$9+EMBALAGEM!G$21+ENTREGA!F$4)*$M$7 -> 893.4139 | H38: =(INTER_EQUIPE!G$13+INTER_VEÍCULO!G$33+((($J38*'HORA PARADA_VEÍCULO'!$K$9)+($D38*'CUSTO KM_VEÍCULO'!$K$9))*H$8)+'HORA PARADA_VEÍCULO'!$K$9+EMBALAGEM!H$21+ENTREGA!G$4)*$M$7 -> 17067.608 | I38: =(INTER_EQUIPE!H$13+INTER_VEÍCULO!H$33+(($J38*'HORA PARADA_VEÍCULO'!N$9)+($D38*'CUSTO KM_VEÍCULO'!N$9)*I$8)+'HORA PARADA_VEÍCULO'!$K$9+EMBALAGEM!I$21+ENTREGA!H$4)*$M$7 -> 893.4139 | J38: ='TABELA DIRETA'!R38 -> 8

Sheet GENERALIDADES
B3: GENERALIDADES DO TRANSPORTE | D3: Fevereiro/2026
B5: Tipo de Cobrança | C5: Forma de Cobrança | E5: Sugestão
A6: 1. | B6: Gerenciamento de Risco - GRIS
B7: - para todas as faixas | C7: s/ o valor da mercadoria | E7: 0.003
B8: - até valor de mercadoria de R$ 2.868,00 cobrar | C8: Por conhecimento | E8: 8.6
A9: 2. | B9: Seguro Fluvial | C9: s/ o valor da mercadoria | E9: 0.05
A10: 3. | B10: Seguro | C10: s/ o valor da mercadoria | E10: 0.02

Sheet EMBALAGEM
B2: Para adaptar a planilha de acordo com a sua realidade basta alterar os valores em verde, referente ao valor unitário (coluna D) e a quantidade de cada item (colunas E, G, I, K, M e O)
B4: GRUPO DE PRODUTOS | C4: MATERIAL DE EMBALAGEM | D4: Valor Unit. | E4: 15 | F4: m³ | G4: 30 | H4: m³ | I4: 45 | J4: m³ | K4: 60 | L4: m³ | M4: 75 | N4: m³ | O4: 90 | P4: m³
B5: CAIXA DE PAPELÃO | C5: CX 1 | D5: 5.27 | E5: 10 | F5: =E5*$D5 -> 52.7 | G5: 25 | H5: =G5*$D5 -> 131.75 | I5: 40 | J5: =I5*$D5 -> 210.8 | K5: 50 | L5: =K5*$D5 -> 263.5 | M5: 60 | N5: =M5*$D5 -> 316.2 | O5: 80 | P5: =O5*$D5 -> 421.6
C6: CX 2 | D6: 8.86 | E6: 15 | F6: =E6*$D6 -> 132.9 | G6: 40 | H6: =G6*$D6 -> 354.4 | I6: 50 | J6: =I6*$D6 -> 443 | K6: 65 | L6: =K6*$D6 -> 575.9 | M6: 75 | N6: =M6*$D6 -> 664.5 | O6: 100 | P6: =O6*$D6 -> 886
C7: CX 4 | D7: 7.19 | E7: 8 | F7: =E7*$D7 -> 57.52 | G7: 20 | H7: =G7*$D7 -> 143.8 | I7: 30 | J7: =I7*$D7 -> 215.7 | K7: 40 | L7: =K7*$D7 -> 287.6 | M7: 40 | N7: =M7*$D7 -> 287.6 | O7: 60 | P7: =O7*$D7 -> 431.4
C8: CX 6 | D8: 13.42 | E8: 4 | F8: =E8*$D8 -> 53.68 | G8: 10 | H8: =G8*$D8 -> 134.2 | I8: 15 | J8: =I8*$D8 -> 201.3 | K8: 20 | L8: =K8*$D8 -> 268.4 | M8: 25 | N8: =M8*$D8 -> 335.5 | O8: 30 | P8: =O8*$D8 -> 402.6
C9: CX P/ TV LCD 40" | D9: 12.07 | E9: 0 | F9: =E9*$D9 -> 0 | G9: 0 | H9: =G9*$D9 -> 0 | I9: 0 | J9: =I9*$D9 -> 0 | K9: 0 | L9: =K9*$D9 -> 0 | M9: 0 | N9: =M9*$D9 -> 0 | O9: 0 | P9: =O9*$D9 -> 0
C10: CX P/ TV LCD 50" | D10: 15.71 | E10: 1 | F10: =E10*$D10 -> 15.71 | G10: 1 | H10: =G10*$D10 -> 15.71 | I10: 1 | J10: =I10*$D10 -> 15.71 | K10: 2 | L10: =K10*$D10 -> 31.42 | M10: 2 | N10: =M10*$D10 -> 31.42 | O10: 2 | P10: =O10*$D10 -> 31.42
C11: CX P/ TV LCD 60" | D11: 16.38 | E11: 0 | F11: =E11*$D11 -> 0 | G11: 1 | H11: =G11*$D11 -> 16.38 | I11: 2 | J11: =I11*$D11 -> 32.76 | K11: 1 | L11: =K11*$D11 -> 16.38 | M11: 2 | N11: =M11*$D11 -> 32.76 | O11: 3 | P11: =O11*$D11 -> 49.14
C12: CX VERDE DUPLEX | D12: 3.35 | E12: 1 | F12: =E12*$D12 -> 3.35 | G12: 1 | H12: =G12*$D12 -> 3.35 | I12: 1 | J12: =I12*$D12 -> 3.35 | K12: 1 | L12: =K12*$D12 -> 3.35 | M12: 1 | N12: =M12*$D12 -> 3.35 | O12: 1 | P12: =O12*$D12 -> 3.35
B13: BOLHA | C13: POLIBOLHA 130X100 METROS | D13: 36 | E13: 1 | F13: =E13*$D13 -> 36 | G13: 2 | H13: =G13*$D13 -> 72 | I13: 3 | J13: =I13*$D13 -> 108 | K13: 4 | L13: =K13*$D13 -> 144 | M13: 5 | N13: =M13*$D13 -> 180 | O13: 6 | P13: =O13*$D13 -> 216
B14: CAPA PLÁSTICA | C14: CAPA SOLTEIRO ESPECIAL | D14: 7.22 | E14: 0 | F14: =E14*$D14 -> 0 | G14: 0 | H14: =G14*$D14 -> 0 | I14: 0 | J14: =I14*$D14 -> 0 | K14: 0 | L14: =K14*$D14 -> 0 | M14: 0 | N14: =M14*$D14 -> 0 | O14: 0 | P14: =O14*$D14 -> 0
C15: CAPA CASAL KING | D15: 12 | E15: 0 | F15: =E15*$D15 -> 0 | G15: 0 | H15: =G15*$D15 -> 0 | I15: 0 | J15: =I15*$D15 -> 0 | K15: 0 | L15: =K15*$D15 -> 0 | M15: 0 | N15: =M15*$D15 -> 0 | O15: 0 | P15: =O15*$D15 -> 0
B16: FITILHOS | C16: FITILHO (1 KG) | D16: 11.2 | E16: 1 | F16: =E16*$D16 -> 11.2 | G16: 1 | H16: =G16*$D16 -> 11.2 | I16: 2 | J16: =I16*$D16 -> 22.4 | K16: 3 | L16: =K16*$D16 -> 33.6 | M16: 3 | N16: =M16*$D16 -> 33.6 | O16: 3 | P16: =O16*$D16 -> 33.6
B17: FITA | C17: FITA ADESIVA 48X50 METROS | D17: 6.73 | E17: 10 | F17: =E17*$D17 -> 67.3 | G17: 15 | H17: =G17*$D17 -> 100.95 | I17: 20 | J17: =I17*$D17 -> 134.6 | K17: 30 | L17: =K17*$D17 -> 201.9 | M17: 40 | N17: =M17*$D17 -> 269.2 | O17: 50 | P17: =O17*$D17 -> 336.5
B18: PAPELÃO | C18: PAPEL MANILHA (10 KG) | D18: 46 | E18: 1 | F18: =E18*$D18 -> 46 | G18: 2 | H18: =G18*$D18 -> 92 | I18: 3 | J18: =I18*$D18 -> 138 | K18: 4 | L18: =K18*$D18 -> 184 | M18: 4 | N18: =M18*$D18 -> 184 | O18: 6 | P18: =O18*$D18 -> 276
C19: PAPEL SEMI-KRAFT (25 KG) | D19: 102 | E19: 0.5 | F19: =E19*$D19 -> 51 | G19: 1 | H19: =G19*$D19 -> 102 | I19: 2 | J19: =I19*$D19 -> 204 | K19: 3 | L19: =K19*$D19 -> 306 | M19: 3 | N19: =M19*$D19 -> 306 | O19: 4 | P19: =O19*$D19 -> 408
C20: ONDULADO DE 120X25 KG | D20: 127.2 | E20: 1 | F20: =E20*$D20 -> 127.2 | G20: 1 | H20: =G20*$D20 -> 127.2 | I20: 2 | J20: =I20*$D20 -> 254.4 | K20: 2 | L20: =K20*$D20 -> 254.4 | M20: 2 | N20: =M20*$D20 -> 254.4 | O20: 2 | P20: =O20*$D20 -> 254.4
B21: TOTAL | F21: =SUM(F5:F20) -> 654.56 | H21: =SUM(H5:H20) -> 1304.94 | J21: =SUM(J5:J20) -> 1984.02 | L21: =SUM(L5:L20) -> 2570.45 | N21: =SUM(N5:N20) -> 2898.53 | P21: =SUM(P5:P20) -> 3750.01

Sheet TX E MARKUP
B2: Para adaptar a planilha de acordo com a sua realidade basta alterar os valores em verde
B5: COMPOSIÇÃO
B7: TIPO | C7: %
B8: TAXA ADMINISTRATIVA | C8: 0.2
B9: COMISSÕES | C9: 0.03
B10: IMPOSTOS FEDERAIS ¹ + INSS DESONERAÇÃO | C10: =3%+0.65%+2%+1.08%+1.5% -> 0.0823
B11: LUCRO | C11: 0.1
B12: ISS | C12: 0.05
B13: ICMS ² | C13: =((12%+7%)/2)*0.8 -> 0.076
B14: ISS | C14: =SUM(C8:C12) -> 0.4623
B15: ICMS | C15: =SUM(C8:C13)-C12 -> 0.4883
B16: MARKUP DIVISOR (LOCAL) | C16: =1/(1-C14) -> 1.8597731
B17: MARKUP DIVISOR (INTERMUNICIPAL) | C17: =1/(1-C15) -> 1.9542701
B19: modelo utiliza as alíquotas do Lucro Presumido *¹
B20: crédito outorgado *²

Sheet FROTA
A2: CUSTOS FROTA
A4: EQUIPAMENTOS | B4: VEÍCULO | C4: TIPO | D4: VALOR | E4: REMUNERAÇÃO | G4: MENSAL
C5: HR | D5: 150039 | E5: 0.01 | G5: =(D5*E5) -> 1500.39
C6: VUC | D6: =250000+26000 -> 276000 | E6: 0.01 | G6: =(D6*E6) -> 2760
C7: TOCO 3/4 | D7: 389859 | E7: 0.01 | G7: =(D7*E7) -> 3898.59
C8: TOCO | D8: 328115 | E8: 0.01 | G8: =(D8*E8) -> 3281.15
C9: TRUCK | D9: =510000+70000 -> 580000 | E9: 0.01 | G9: =(D9*E9) -> 5800
C10: CARRETA | D10: =565000+30000 -> 595000 | E10: 0.01 | G10: =(D10*E10) -> 5950
B11: EQUIPAMENTO | C11: MONITORAMENTO VIA SATÉLITE | G11: 57
A13: MANUTENÇÃO | B13: PNEUS | C13: CUSTO DE MANUTENÇÃO POR KM RODADO | G13: 0.35
C14: TIPO | D14: PNEU | E14: KM | F14: QTDE. | G14: VALOR
C15: HR | D15: 735 | E15: 70000 | F15: 4 | G15: =F15*(D15/E15) -> 0.042
C16: VUC | D16: =603.8+345 -> 948.8 | E16: 10000 | F16: 4 | G16: =F16*(D16/E16) -> 0.37952
C17: TOCO 3/4 | D17: 1436.69 | E17: 200000 | F17: 6 | G17: =F17*(D17/E17) -> 0.0431007
C18: TOCO | D18: 2822.23 | E18: =90000+80000+80000 -> 250000 | F18: 6 | G18: =F18*(D18/E18) -> 0.06773352
C19: TRUCK | D19: =2430+588+588 -> 3606 | E19: =90000+80000+80000 -> 250000 | F19: 10 | G19: =F19*(D19/E19) -> 0.14424
C20: CARRETA | D20: =2430+588+588 -> 3606 | E20: =90000+80000+80000 -> 250000 | F20: 12 | G20: =F20*(D20/E20) -> 0.173088
A22: LICENÇAS E SEGUROS | B22: IPVA | C22: TIPO | D22: DESPESA ANUAL | F22: QTDE. | G22: MENSAL
C23: HR | D23: =(2%*D5) -> 3000.78 | F23: 12 | G23: =D23/F23 -> 250.065
C24: VUC | D24: =(2%*D6) -> 5520 | F24: 12 | G24: =D24/F24 -> 460
C25: TOCO 3/4 | D25: =(1.5%*D7) -> 5847.885 | F25: 12 | G25: =D25/F25 -> 487.32375
C26: TOCO | D26: =(1.5%*D8) -> 4921.725 | F26: 12 | G26: =D26/F26 -> 410.14375
C27: TRUCK | D27: =(1.5%*D9) -> 8700 | F27: 12 | G27: =D27/F27 -> 725
C28: CARRETA | D28: =(1.5%*D10) -> 8925 | F28: 12 | G28: =D28/F28 -> 743.75
B29: LICENCIAMENTO | D29: 144.86 | F29: 12 | G29: =D29/F29 -> 12.071667
B30: HONORÁRIOS DESPACHANTE | D30: 90 | F30: 12 | G30: =D30/F30 -> 7.5
B31: SEGURO CONTRA TERCEIROS | D31: =170362.23/69 -> 2469.0178 | F31: 12 | G31: =D31/F31 -> 205.75149
A33: COMBUSTÍVEL | B33: CONSUMO | C33: PREÇO MÉDIO DO ÓLEO DIESEL | G33: 5.96
C34: HR | F34: 10 | G34: =G$33/F34 -> 0.596
C35: VUC | F35: 8 | G35: =G$33/F35 -> 0.745
C36: TOCO 3/4 | F36: 5 | G36: =G$33/F36 -> 1.192
C37: TOCO | F37: 4.2 | G37: =G$33/F37 -> 1.4190476
C38: TRUCK | F38: 3.5 | G38: =G$33/F38 -> 1.7028571
C39: CARRETA | F39: 3 | G39: =G$33/F39 -> 1.9866667
A41: MOTORISTA | B41: CUSTO MOTORISTA / DIA | G41: =RECURSOS!B8 -> 191.54094
B42: DV (JANTA E PERNOITE) / DIA | G42: =35+50 -> 85
A44: CUSTO DIÁRIA PARADO (VEÍCULO + MOTORISTA) | B44: HR | F44: 22 | G44: =((G5+$G$11+G23+$G$29+$G$30+G$31)/F44)+$G$41 -> 283.93995
B45: VUC | F45: 22 | G45: =((G6+$G$11+G24+$G$29+$G$30+G$31)/F45)+$G$41 -> 350.73745
B46: TOCO 3/4 | F46: 22 | G46: =((G7+$G$11+G25+$G$29+$G$30+G$31)/F46)+$G$41 -> 403.73353
B47: TOCO | F47: 22 | G47: =((G8+$G$11+G26+$G$29+$G$30+G$31)/F47)+$G$41 -> 372.15989
...

Sheet RECURSOS
A2: RECURSOS
A4: MÃO DE OBRA
A5: Função | B5: Diária
A6: Chefe de Equipe | B6: =VLOOKUP(A6,'FOLHA DE PAGAMENTO'!B:W,22,0) -> 173.86672
A7: Embalador | B7: =VLOOKUP(A7,'FOLHA DE PAGAMENTO'!B:W,22,0) -> 154.26195
A8: Motorista | B8: =VLOOKUP(A8,'FOLHA DE PAGAMENTO'!B:W,22,0) -> 191.54094

Sheet FOLHA DE PAGAMENTO
B1: Função | C1: Salário Nominal | D1: Salário | E1: VT Dia | F1: VT | G1: Desconto VT | H1: Alimentação Dia | I1: Alimentação | J1: Odonto | K1: INSS Terceiros | L1: FGTS | M1: Provisão 13º | N1: Provisão INSS Terceiros 13º | O1: Provisão FGTS 13º | P1: Provisão Férias + 1/3 Férias | Q1: Provisão INSS 1/3 Férias | R1: Provisão FGTS Férias | S1: PLR Anual | T1: Provisão PLR | U1: Provisão Rescisões | V1: Custo Mensal | W1: Custo Diária
B2: Chefe de Equipe | C2: 2216.59 | D2: =C2*11/12 -> 2031.8742 | E2: 13.43 | F2: =E2*22 -> 295.46 | G2: =IF(F2>0,C2*0.06,0) -> 132.9954 | H2: 27.14 | I2: =H2*22 -> 597.08 | J2: 23 | K2: =D2*0.088 -> 178.80493 | L2: =D2*0.08 -> 162.54993 | M2: =C2/12 -> 184.71583 | N2: =M2*0.058 -> 10.713518 | O2: =M2*0.08 -> 14.777267 | P2: =M2+(M2/3) -> 246.28778 | Q2: =P2*0.058 -> 14.284691 | R2: =P2*0.08 -> 19.703022 | S2: 1200 | T2: =S2/12 -> 100 | U2: =(L2+O2+R2)*0.4 -> 78.812089 | V2: =D2+F2-G2+I2+J2+K2+L2+M2+N2+O2+P2+Q2+R2+T2+U2 -> 3825.0678 | W2: =V2/22 -> 173.86672
B3: Embalador | C3: 1876.31 | D3: =C3*11/12 -> 1719.9508 | E3: 13.43 | F3: =E3*22 -> 295.46 | G3: =IF(F3>0,C3*0.06,0) -> 112.5786 | H3: 27.14 | I3: =H3*22 -> 597.08 | J3: 23 | K3: =D3*0.088 -> 151.35567 | L3: =D3*0.08 -> 137.59607 | M3: =C3/12 -> 156.35917 | N3: =M3*0.058 -> 9.0688317 | O3: =M3*0.08 -> 12.508733 | P3: =M3+(M3/3) -> 208.47889 | Q3: =P3*0.058 -> 12.091776 | R3: =P3*0.08 -> 16.678311 | S3: 1200 | T3: =S3/12 -> 100 | U3: =(L3+O3+R3)*0.4 -> 66.713244 | V3: =D3+F3-G3+I3+J3+K3+L3+M3+N3+O3+P3+Q3+R3+T3+U3 -> 3393.7629 | W3: =V3/22 -> 154.26195
B4: Motorista | C4: 2631.88 | D4: =C4*11/12 -> 2412.5567 | E4: 0 | F4: =E4*22 -> 0 | G4: =IF(F4>0,C4*0.06,0) -> 0 | H4: 27.14 | I4: =H4*22 -> 597.08 | J4: 23 | K4: =D4*0.088 -> 212.30499 | L4: =D4*0.08 -> 193.00453 | M4: =C4/12 -> 219.32333 | N4: =M4*0.058 -> 12.720753 | O4: =M4*0.08 -> 17.545867 | P4: =M4+(M4/3) -> 292.43111 | Q4: =P4*0.058 -> 16.961004 | R4: =P4*0.08 -> 23.394489 | S4: 1200 | T4: =S4/12 -> 100 | U4: =(L4+O4+R4)*0.4 -> 93.577956 | V4: =D4+F4-G4+I4+J4+K4+L4+M4+N4+O4+P4+Q4+R4+T4+U4 -> 4213.9007 | W4: =V4/22 -> 191.54094
B6: FUNÇÃO | C6: CHEFE DE EQUIPE | D6: EMBALADOR | E6: MOTORISTA
B7: Salário Nominal | C7: 2371.7513 | D7: 2007.6517 | E7: 2816.12
B8: Salário | C8: =C7*11/12 -> 2174.1054 | D8: =D7*11/12 -> 1840.3474 | E8: =E7*11/12 -> 2581.4433
B9: VT Dia | C9: 13.43 | D9: 13.43 | E9: 0
B10: VT | C10: =C9*22 -> 295.46 | D10: =D9*22 -> 295.46 | E10: =E9*22 -> 0
B11: Desconto VT | C11: =IF(C10>0,C7*0.06,0) -> 142.30508 | D11: =IF(D10>0,D7*0.06,0) -> 120.4591 | E11: =IF(E10>0,E7*0.06,0) -> 0
B12: Alimentação Dia | C12: 35 | D12: 35 | E12: 35
B13: Alimentação | C13: =C12*22 -> 770 | D13: =D12*22 -> 770 | E13: =E12*22 -> 770
B14: Odonto | C14: 23 | D14: 23 | E14: 23
B15: INSS Terceiros | C15: =C8*0.088 -> 191.32127 | D15: =D8*0.088 -> 161.95057 | E15: =E8*0.088 -> 227.16701
B16: FGTS | C16: =C8*0.08 -> 173.92843 | D16: =D8*0.08 -> 147.22779 | E16: =E8*0.08 -> 206.51547
B17: Provisão 13º | C17: =C7/12 -> 197.64594 | D17: =D7/12 -> 167.30431 | E17: =E7/12 -> 234.67667
B18: Provisão INSS Terceiros 13º | C18: =C17*0.058 -> 11.463465 | D18: =D17*0.058 -> 9.7036499 | E18: =E17*0.058 -> 13.611247
B19: Provisão FGTS 13º | C19: =C17*0.08 -> 15.811675 | D19: =D17*0.08 -> 13.384345 | E19: =E17*0.08 -> 18.774133
B20: Provisão Férias + 1/3 Férias | C20: =C17+(C17/3) -> 263.52792 | D20: =D17+(D17/3) -> 223.07241 | E20: =E17+(E17/3) -> 312.90222
B21: Provisão INSS 1/3 Férias | C21: =C20*0.058 -> 15.284619 | D21: =D20*0.058 -> 12.9382 | E21: =E20*0.058 -> 18.148329
B22: Provisão FGTS Férias | C22: =C20*0.08 -> 21.082234 | D22: =D20*0.08 -> 17.845793 | E22: =E20*0.08 -> 25.032178
B23: PLR Anual | C23: 1500 | D23: 1500 | E23: 1500
B24: Provisão PLR | C24: =C23/12 -> 125 | D24: =D23/12 -> 125 | E24: =E23/12 -> 125
B25: Provisão Rescisões | C25: =(C16+C19+C22)*0.4 -> 84.328935 | D25: =(D16+D19+D22)*0.4 -> 71.383172 | E25: =(E16+E19+E22)*0.4 -> 100.12871
B26: Custo Mensal | C26: =C8+C10-C11+C13+C14+C15+C16+C17+C18+C19+C20+C21+C22+C24+C25 -> 4219.6548 | D26: =D8+D10-D11+D13+D14+D15+D16+D17+D18+D19+D20+D21+D22+D24+D25 -> 3758.1585 | E26: =E8+E10-E11+E13+E14+E15+E16+E17+E18+E19+E20+E21+E22+E24+E25 -> 4656.3993
B27: Custo Diária | C27: =C26/22 -> 191.80249 | D27: =D26/22 -> 170.82539 | E27: =E26/22 -> 211.65451

Sheet EQUIPE DE ENTREGA
B2: AJUDANTES PARA ENTREGA
B3: M³ | C3: QTDE. | D3: VALOR
B4: 15 | C4: 2 | D4: =C4*$D$11 -> 320
B5: 30 | C5: 3 | D5: =C5*$D$11 -> 480
B6: 45 | C6: 4 | D6: =C6*$D$11 -> 640
B7: 60 | C7: 5 | D7: =C7*$D$11 -> 800
B8: 75 | C8: 6 | D8: =C8*$D$11 -> 960
B9: 90 | C9: 7 | D9: =C9*$D$11 -> 1120
D11: 160 | E11: valor por ajudante para entrega

Sheet LOCAL_EQUIPE
B2: EQUIPE NECESSÁRIA POR FAIXA DE VOLUME M³ | C2: TIPO | D2: 15 | F2: 30 | H2: 45 | J2: 60 | L2: 75 | N2: 90
B3: EMBALAGEM ANTECIPADA 1 | C3: CHEFE DE EQUIPE | D3: 0 | E3: =VLOOKUP($C3,RECURSOS!$A:$B,2,0)*D3 -> 0 | F3: 1 | G3: =VLOOKUP($C3,RECURSOS!$A:$B,2,0)*F3 -> 173.86672 | H3: 1 | I3: =VLOOKUP($C3,RECURSOS!$A:$B,2,0)*H3 -> 173.86672 | J3: 1 | K3: =VLOOKUP($C3,RECURSOS!$A:$B,2,0)*J3 -> 173.86672 | L3: 1 | M3: =VLOOKUP($C3,RECURSOS!$A:$B,2,0)*L3 -> 173.86672 | N3: 1 | O3: =VLOOKUP($C3,RECURSOS!$A:$B,2,0)*N3 -> 173.86672
C4: EMBALADOR | D4: 0 | E4: =VLOOKUP($C4,RECURSOS!$A:$B,2,0)*D4 -> 0 | F4: 2 | G4: =VLOOKUP($C4,RECURSOS!$A:$B,2,0)*F4 -> 308.5239 | H4: 3 | I4: =VLOOKUP($C4,RECURSOS!$A:$B,2,0)*H4 -> 462.78585 | J4: 3 | K4: =VLOOKUP($C4,RECURSOS!$A:$B,2,0)*J4 -> 462.78585 | L4: 2 | M4: =VLOOKUP($C4,RECURSOS!$A:$B,2,0)*L4 -> 308.5239 | N4: 3 | O4: =VLOOKUP($C4,RECURSOS!$A:$B,2,0)*N4 -> 462.78585
B5: EMBALAGEM ANTECIPADA 2 | C5: CHEFE DE EQUIPE | D5: 0 | E5: =VLOOKUP($C5,RECURSOS!$A:$B,2,0)*D5 -> 0 | F5: 0 | G5: =VLOOKUP($C5,RECURSOS!$A:$B,2,0)*F5 -> 0 | H5: 0 | I5: =VLOOKUP($C5,RECURSOS!$A:$B,2,0)*H5 -> 0 | J5: 0 | K5: =VLOOKUP($C5,RECURSOS!$A:$B,2,0)*J5 -> 0 | L5: 1 | M5: =VLOOKUP($C5,RECURSOS!$A:$B,2,0)*L5 -> 173.86672 | N5: 1 | O5: =VLOOKUP($C5,RECURSOS!$A:$B,2,0)*N5 -> 173.86672
C6: EMBALADOR | D6: 0 | E6: =VLOOKUP($C6,RECURSOS!$A:$B,2,0)*D6 -> 0 | F6: 0 | G6: =VLOOKUP($C6,RECURSOS!$A:$B,2,0)*F6 -> 0 | H6: 0 | I6: =VLOOKUP($C6,RECURSOS!$A:$B,2,0)*H6 -> 0 | J6: 0 | K6: =VLOOKUP($C6,RECURSOS!$A:$B,2,0)*J6 -> 0 | L6: 2 | M6: =VLOOKUP($C6,RECURSOS!$A:$B,2,0)*L6 -> 308.5239 | N6: 3 | O6: =VLOOKUP($C6,RECURSOS!$A:$B,2,0)*N6 -> 462.78585
B7: EMBALAGEM/APANHA | C7: CHEFE DE EQUIPE | D7: 0 | E7: =VLOOKUP($C7,RECURSOS!$A:$B,2,0)*D7 -> 0 | F7: 0 | G7: =VLOOKUP($C7,RECURSOS!$A:$B,2,0)*F7 -> 0 | H7: 0 | I7: =VLOOKUP($C7,RECURSOS!$A:$B,2,0)*H7 -> 0 | J7: 0 | K7: =VLOOKUP($C7,RECURSOS!$A:$B,2,0)*J7 -> 0 | L7: 0 | M7: =VLOOKUP($C7,RECURSOS!$A:$B,2,0)*L7 -> 0 | N7: 0 | O7: =VLOOKUP($C7,RECURSOS!$A:$B,2,0)*N7 -> 0
C8: EMBALADOR | D8: 0 | E8: =VLOOKUP($C8,RECURSOS!$A:$B,2,0)*D8 -> 0 | F8: 0 | G8: =VLOOKUP($C8,RECURSOS!$A:$B,2,0)*F8 -> 0 | H8: 0 | I8: =VLOOKUP($C8,RECURSOS!$A:$B,2,0)*H8 -> 0 | J8: 0 | K8: =VLOOKUP($C8,RECURSOS!$A:$B,2,0)*J8 -> 0 | L8: 0 | M8: =VLOOKUP($C8,RECURSOS!$A:$B,2,0)*L8 -> 0 | N8: 0 | O8: =VLOOKUP($C8,RECURSOS!$A:$B,2,0)*N8 -> 0
B9: EMBALAGEM/APANHA/ENTREGA | C9: CHEFE DE EQUIPE | D9: 1 | E9: =VLOOKUP($C9,RECURSOS!$A:$B,2,0)*D9 -> 173.86672 | F9: 0 | G9: =VLOOKUP($C9,RECURSOS!$A:$B,2,0)*F9 -> 0 | H9: 0 | I9: =VLOOKUP($C9,RECURSOS!$A:$B,2,0)*H9 -> 0 | J9: 0 | K9: =VLOOKUP($C9,RECURSOS!$A:$B,2,0)*J9 -> 0 | L9: 0 | M9: =VLOOKUP($C9,RECURSOS!$A:$B,2,0)*L9 -> 0 | N9: 0 | O9: =VLOOKUP($C9,RECURSOS!$A:$B,2,0)*N9 -> 0
C10: EMBALADOR | D10: 3 | E10: =VLOOKUP($C10,RECURSOS!$A:$B,2,0)*D10 -> 462.78585 | F10: 0 | G10: =VLOOKUP($C10,RECURSOS!$A:$B,2,0)*F10 -> 0 | H10: 0 | I10: =VLOOKUP($C10,RECURSOS!$A:$B,2,0)*H10 -> 0 | J10: 0 | K10: =VLOOKUP($C10,RECURSOS!$A:$B,2,0)*J10 -> 0 | L10: 0 | M10: =VLOOKUP($C10,RECURSOS!$A:$B,2,0)*L10 -> 0 | N10: 0 | O10: =VLOOKUP($C10,RECURSOS!$A:$B,2,0)*N10 -> 0
B11: APANHA 1 | C11: CHEFE DE EQUIPE | D11: 0 | E11: =VLOOKUP($C11,RECURSOS!$A:$B,2,0)*D11 -> 0 | F11: 0 | G11: =VLOOKUP($C11,RECURSOS!$A:$B,2,0)*F11 -> 0 | H11: 0 | I11: =VLOOKUP($C11,RECURSOS!$A:$B,2,0)*H11 -> 0 | J11: 0 | K11: =VLOOKUP($C11,RECURSOS!$A:$B,2,0)*J11 -> 0 | L11: 0 | M11: =VLOOKUP($C11,RECURSOS!$A:$B,2,0)*L11 -> 0 | N11: 0 | O11: =VLOOKUP($C11,RECURSOS!$A:$B,2,0)*N11 -> 0
C12: EMBALADOR | D12: 0 | E12: =VLOOKUP($C12,RECURSOS!$A:$B,2,0)*D12 -> 0 | F12: 0 | G12: =VLOOKUP($C12,RECURSOS!$A:$B,2,0)*F12 -> 0 | H12: 0 | I12: =VLOOKUP($C12,RECURSOS!$A:$B,2,0)*H12 -> 0 | J12: 0 | K12: =VLOOKUP($C12,RECURSOS!$A:$B,2,0)*J12 -> 0 | L12: 0 | M12: =VLOOKUP($C12,RECURSOS!$A:$B,2,0)*L12 -> 0 | N12: 0 | O12: =VLOOKUP($C12,RECURSOS!$A:$B,2,0)*N12 -> 0
B13: APANHA 2 | C13: CHEFE DE EQUIPE | D13: 0 | E13: =VLOOKUP($C13,RECURSOS!$A:$B,2,0)*D13 -> 0 | F13: 0 | G13: =VLOOKUP($C13,RECURSOS!$A:$B,2,0)*F13 -> 0 | H13: 0 | I13: =VLOOKUP($C13,RECURSOS!$A:$B,2,0)*H13 -> 0 | J13: 0 | K13: =VLOOKUP($C13,RECURSOS!$A:$B,2,0)*J13 -> 0 | L13: 0 | M13: =VLOOKUP($C13,RECURSOS!$A:$B,2,0)*L13 -> 0 | N13: 0 | O13: =VLOOKUP($C13,RECURSOS!$A:$B,2,0)*N13 -> 0
C14: EMBALADOR | D14: 0 | E14: =VLOOKUP($C14,RECURSOS!$A:$B,2,0)*D14 -> 0 | F14: 0 | G14: =VLOOKUP($C14,RECURSOS!$A:$B,2,0)*F14 -> 0 | H14: 0 | I14: =VLOOKUP($C14,RECURSOS!$A:$B,2,0)*H14 -> 0 | J14: 0 | K14: =VLOOKUP($C14,RECURSOS!$A:$B,2,0)*J14 -> 0 | L14: 0 | M14: =VLOOKUP($C14,RECURSOS!$A:$B,2,0)*L14 -> 0 | N14: 0 | O14: =VLOOKUP($C14,RECURSOS!$A:$B,2,0)*N14 -> 0
B15: APANHA/ENTREGA 1 | C15: CHEFE DE EQUIPE | D15: 0 | E15: =VLOOKUP($C15,RECURSOS!$A:$B,2,0)*D15 -> 0 | F15: 1 | G15: =VLOOKUP($C15,RECURSOS!$A:$B,2,0)*F15 -> 173.86672 | H15: 1 | I15: =VLOOKUP($C15,RECURSOS!$A:$B,2,0)*H15 -> 173.86672 | J15: 1 | K15: =VLOOKUP($C15,RECURSOS!$A:$B,2,0)*J15 -> 173.86672 | L15: 1 | M15: =VLOOKUP($C15,RECURSOS!$A:$B,2,0)*L15 -> 173.86672 | N15: 1 | O15: =VLOOKUP($C15,RECURSOS!$A:$B,2,0)*N15 -> 173.86672
C16: EMBALADOR | D16: 0 | E16: =VLOOKUP($C16,RECURSOS!$A:$B,2,0)*D16 -> 0 | F16: 5 | G16: =VLOOKUP($C16,RECURSOS!$A:$B,2,0)*F16 -> 771.30976 | H16: 5 | I16: =VLOOKUP($C16,RECURSOS!$A:$B,2,0)*H16 -> 771.30976 | J16: 5 | K16: =VLOOKUP($C16,RECURSOS!$A:$B,2,0)*J16 -> 771.30976 | L16: 5 | M16: =VLOOKUP($C16,RECURSOS!$A:$B,2,0)*L16 -> 771.30976 | N16: 5 | O16: =VLOOKUP($C16,RECURSOS!$A:$B,2,0)*N16 -> 771.30976
B17: APANHA/ENTREGA 2 | C17: CHEFE DE EQUIPE | D17: 0 | E17: =VLOOKUP($C17,RECURSOS!$A:$B,2,0)*D17 -> 0 | F17: 0 | G17: =VLOOKUP($C17,RECURSOS!$A:$B,2,0)*F17 -> 0 | H17: 0 | I17: =VLOOKUP($C17,RECURSOS!$A:$B,2,0)*H17 -> 0 | J17: 1 | K17: =VLOOKUP($C17,RECURSOS!$A:$B,2,0)*J17 -> 173.86672 | L17: 1 | M17: =VLOOKUP($C17,RECURSOS!$A:$B,2,0)*L17 -> 173.86672 | N17: 1 | O17: =VLOOKUP($C17,RECURSOS!$A:$B,2,0)*N17 -> 173.86672
C18: EMBALADOR | D18: 0 | E18: =VLOOKUP($C18,RECURSOS!$A:$B,2,0)*D18 -> 0 | F18: 0 | G18: =VLOOKUP($C18,RECURSOS!$A:$B,2,0)*F18 -> 0 | H18: 0 | I18: =VLOOKUP($C18,RECURSOS!$A:$B,2,0)*H18 -> 0 | J18: 5 | K18: =VLOOKUP($C18,RECURSOS!$A:$B,2,0)*J18 -> 771.30976 | L18: 5 | M18: =VLOOKUP($C18,RECURSOS!$A:$B,2,0)*L18 -> 771.30976 | N18: 5 | O18: =VLOOKUP($C18,RECURSOS!$A:$B,2,0)*N18 -> 771.30976
B19: APANHA/ENTREGA 3 | C19: CHEFE DE EQUIPE | D19: 0 | E19: =VLOOKUP($C19,RECURSOS!$A:$B,2,0)*D19 -> 0 | F19: 0 | G19: =VLOOKUP($C19,RECURSOS!$A:$B,2,0)*F19 -> 0 | H19: 0 | I19: =VLOOKUP($C19,RECURSOS!$A:$B,2,0)*H19 -> 0 | J19: 0 | K19: =VLOOKUP($C19,RECURSOS!$A:$B,2,0)*J19 -> 0 | L19: 0 | M19: =VLOOKUP($C19,RECURSOS!$A:$B,2,0)*L19 -> 0 | N19: 1 | O19: =VLOOKUP($C19,RECURSOS!$A:$B,2,0)*N19 -> 173.86672
C20: EMBALADOR | D20: 0 | E20: =VLOOKUP($C20,RECURSOS!$A:$B,2,0)*D20 -> 0 | F20: 0 | G20: =VLOOKUP($C20,RECURSOS!$A:$B,2,0)*F20 -> 0 | H20: 0 | I20: =VLOOKUP($C20,RECURSOS!$A:$B,2,0)*H20 -> 0 | J20: 0 | K20: =VLOOKUP($C20,RECURSOS!$A:$B,2,0)*J20 -> 0 | L20: 0 | M20: =VLOOKUP($C20,RECURSOS!$A:$B,2,0)*L20 -> 0 | N20: 5 | O20: =VLOOKUP($C20,RECURSOS!$A:$B,2,0)*N20 -> 771.30976
E21: =SUM(E3:E20) -> 636.65257 | G21: =SUM(G3:G20) -> 1427.5671 | I21: =SUM(I3:I20) -> 1581.829 | K21: =SUM(K3:K20) -> 2527.0055 | M21: =SUM(M3:M20) -> 2855.1342 | O21: =SUM(O3:O20) -> 4108.8346

Sheet LOCAL_VEÍCULO
B2: VEÍCULO NECESSÁRIO POR FAIXA DE VOLUME M³ | C2: TIPO | D2: 15 | F2: 30 | H2: 45 | J2: 60 | L2: 75 | N2: 90
B3: EMBALAGEM ANTECIPADA 1 | C3: HR | D3: 0 | E3: =VLOOKUP($C3,FROTA!$B$58:$G$63,6,0)*D3 -> 0 | F3: 1 | G3: =VLOOKUP($C3,FROTA!$B$58:$G$63,6,0)*F3 -> 333.33995 | H3: 0 | I3: =VLOOKUP($C3,FROTA!$B$58:$G$63,6,0)*H3 -> 0 | J3: 0 | K3: =VLOOKUP($C3,FROTA!$B$58:$G$63,6,0)*J3 -> 0 | L3: 1 | M3: =VLOOKUP($C3,FROTA!$B$58:$G$63,6,0)*L3 -> 333.33995 | N3: 0 | O3: =VLOOKUP($C3,FROTA!$B$58:$G$63,6,0)*N3 -> 0
C4: VUC | D4: 0 | E4: =VLOOKUP($C4,FROTA!$B$58:$G$63,6,0)*D4 -> 0 | F4: 0 | G4: =VLOOKUP($C4,FROTA!$B$58:$G$63,6,0)*F4 -> 0 | H4: 1 | I4: =VLOOKUP($C4,FROTA!$B$58:$G$63,6,0)*H4 -> 424.46345 | J4: 1 | K4: =VLOOKUP($C4,FROTA!$B$58:$G$63,6,0)*J4 -> 424.46345 | L4: 0 | M4: =VLOOKUP($C4,FROTA!$B$58:$G$63,6,0)*L4 -> 0 | N4: 1 | O4: =VLOOKUP($C4,FROTA!$B$58:$G$63,6,0)*N4 -> 424.46345
C5: TOCO 3/4 | D5: 0 | E5: =VLOOKUP($C5,FROTA!$B$58:$G$63,6,0)*D5 -> 0 | F5: 0 | G5: =VLOOKUP($C5,FROTA!$B$58:$G$63,6,0)*F5 -> 0 | H5: 0 | I5: =VLOOKUP($C5,FROTA!$B$58:$G$63,6,0)*H5 -> 0 | J5: 0 | K5: =VLOOKUP($C5,FROTA!$B$58:$G$63,6,0)*J5 -> 0 | L5: 0 | M5: =VLOOKUP($C5,FROTA!$B$58:$G$63,6,0)*L5 -> 0 | N5: 0 | O5: =VLOOKUP($C5,FROTA!$B$58:$G$63,6,0)*N5 -> 0
C6: TOCO | D6: 0 | E6: =VLOOKUP($C6,FROTA!$B$58:$G$63,6,0)*D6 -> 0 | F6: 0 | G6: =VLOOKUP($C6,FROTA!$B$58:$G$63,6,0)*F6 -> 0 | H6: 0 | I6: =VLOOKUP($C6,FROTA!$B$58:$G$63,6,0)*H6 -> 0 | J6: 0 | K6: =VLOOKUP($C6,FROTA!$B$58:$G$63,6,0)*J6 -> 0 | L6: 0 | M6: =VLOOKUP($C6,FROTA!$B$58:$G$63,6,0)*L6 -> 0 | N6: 0 | O6: =VLOOKUP($C6,FROTA!$B$58:$G$63,6,0)*N6 -> 0
C7: TRUCK | D7: 0 | E7: =VLOOKUP($C7,FROTA!$B$58:$G$63,6,0)*D7 -> 0 | F7: 0 | G7: =VLOOKUP($C7,FROTA!$B$58:$G$63,6,0)*F7 -> 0 | H7: 0 | I7: =VLOOKUP($C7,FROTA!$B$58:$G$63,6,0)*H7 -> 0 | J7: 0 | K7: =VLOOKUP($C7,FROTA!$B$58:$G$63,6,0)*J7 -> 0 | L7: 0 | M7: =VLOOKUP($C7,FROTA!$B$58:$G$63,6,0)*L7 -> 0 | N7: 0 | O7: =VLOOKUP($C7,FROTA!$B$58:$G$63,6,0)*N7 -> 0
C8: CARRETA | D8: 0 | E8: =VLOOKUP($C8,FROTA!$B$58:$G$63,6,0)*D8 -> 0 | F8: 0 | G8: =VLOOKUP($C8,FROTA!$B$58:$G$63,6,0)*F8 -> 0 | H8: 0 | I8: =VLOOKUP($C8,FROTA!$B$58:$G$63,6,0)*H8 -> 0 | J8: 0 | K8: =VLOOKUP($C8,FROTA!$B$58:$G$63,6,0)*J8 -> 0 | L8: 0 | M8: =VLOOKUP($C8,FROTA!$B$58:$G$63,6,0)*L8 -> 0 | N8: 0 | O8: =VLOOKUP($C8,FROTA!$B$58:$G$63,6,0)*N8 -> 0
B9: EMBALAGEM ANTECIPADA 2 | C9: HR | D9: 0 | E9: =VLOOKUP($C9,FROTA!$B$58:$G$63,6,0)*D9 -> 0 | F9: 0 | G9: =VLOOKUP($C9,FROTA!$B$58:$G$63,6,0)*F9 -> 0 | H9: 0 | I9: =VLOOKUP($C9,FROTA!$B$58:$G$63,6,0)*H9 -> 0 | J9: 0 | K9: =VLOOKUP($C9,FROTA!$B$58:$G$63,6,0)*J9 -> 0 | L9: 1 | M9: =VLOOKUP($C9,FROTA!$B$58:$G$63,6,0)*L9 -> 333.33995 | N9: 0 | O9: =VLOOKUP($C9,FROTA!$B$58:$G$63,6,0)*N9 -> 0
C10: VUC | D10: 0 | E10: =VLOOKUP($C10,FROTA!$B$58:$G$63,6,0)*D10 -> 0 | F10: 0 | G10: =VLOOKUP($C10,FROTA!$B$58:$G$63,6,0)*F10 -> 0 | H10: 0 | I10: =VLOOKUP($C10,FROTA!$B$58:$G$63,6,0)*H10 -> 0 | J10: 0 | K10: =VLOOKUP($C10,FROTA!$B$58:$G$63,6,0)*J10 -> 0 | L10: 0 | M10: =VLOOKUP($C10,FROTA!$B$58:$G$63,6,0)*L10 -> 0 | N10: 1 | O10: =VLOOKUP($C10,FROTA!$B$58:$G$63,6,0)*N10 -> 424.46345
C11: TOCO 3/4 | D11: 0 | E11: =VLOOKUP($C11,FROTA!$B$58:$G$63,6,0)*D11 -> 0 | F11: 0 | G11: =VLOOKUP($C11,FROTA!$B$58:$G$63,6,0)*F11 -> 0 | H11: 0 | I11: =VLOOKUP($C11,FROTA!$B$58:$G$63,6,0)*H11 -> 0 | J11: 0 | K11: =VLOOKUP($C11,FROTA!$B$58:$G$63,6,0)*J11 -> 0 | L11: 0 | M11: =VLOOKUP($C11,FROTA!$B$58:$G$63,6,0)*L11 -> 0 | N11: 0 | O11: =VLOOKUP($C11,FROTA!$B$58:$G$63,6,0)*N11 -> 0
C12: TOCO | D12: 0 | E12: =VLOOKUP($C12,FROTA!$B$58:$G$63,6,0)*D12 -> 0 | F12: 0 | G12: =VLOOKUP($C12,FROTA!$B$58:$G$63,6,0)*F12 -> 0 | H12: 0 | I12: =VLOOKUP($C12,FROTA!$B$58:$G$63,6,0)*H12 -> 0 | J12: 0 | K12: =VLOOKUP($C12,FROTA!$B$58:$G$63,6,0)*J12 -> 0 | L12: 0 | M12: =VLOOKUP($C12,FROTA!$B$58:$G$63,6,0)*L12 -> 0 | N12: 0 | O12: =VLOOKUP($C12,FROTA!$B$58:$G$63,6,0)*N12 -> 0
C13: TRUCK | D13: 0 | E13: =VLOOKUP($C13,FROTA!$B$58:$G$63,6,0)*D13 -> 0 | F13: 0 | G13: =VLOOKUP($C13,FROTA!$B$58:$G$63,6,0)*F13 -> 0 | H13: 0 | I13: =VLOOKUP($C13,FROTA!$B$58:$G$63,6,0)*H13 -> 0 | J13: 0 | K13: =VLOOKUP($C13,FROTA!$B$58:$G$63,6,0)*J13 -> 0 | L13: 0 | M13: =VLOOKUP($C13,FROTA!$B$58:$G$63,6,0)*L13 -> 0 | N13: 0 | O13: =VLOOKUP($C13,FROTA!$B$58:$G$63,6,0)*N13 -> 0
C14: CARRETA | D14: 0 | E14: =VLOOKUP($C14,FROTA!$B$58:$G$63,6,0)*D14 -> 0 | F14: 0 | G14: =VLOOKUP($C14,FROTA!$B$58:$G$63,6,0)*F14 -> 0 | H14: 0 | I14: =VLOOKUP($C14,FROTA!$B$58:$G$63,6,0)*H14 -> 0 | J14: 0 | K14: =VLOOKUP($C14,FROTA!$B$58:$G$63,6,0)*J14 -> 0 | L14: 0 | M14: =VLOOKUP($C14,FROTA!$B$58:$G$63,6,0)*L14 -> 0 | N14: 0 | O14: =VLOOKUP($C14,FROTA!$B$58:$G$63,6,0)*N14 -> 0
B15: EMBALAGEM/APANHA | C15: HR | D15: 0 | E15: =VLOOKUP($C15,FROTA!$B$58:$G$63,6,0)*D15 -> 0 | F15: 0 | G15: =VLOOKUP($C15,FROTA!$B$58:$G$63,6,0)*F15 -> 0 | H15: 0 | I15: =VLOOKUP($C15,FROTA!$B$58:$G$63,6,0)*H15 -> 0 | J15: 0 | K15: =VLOOKUP($C15,FROTA!$B$58:$G$63,6,0)*J15 -> 0 | L15: 0 | M15: =VLOOKUP($C15,FROTA!$B$58:$G$63,6,0)*L15 -> 0 | N15: 0 | O15: =VLOOKUP($C15,FROTA!$B$58:$G$63,6,0)*N15 -> 0
C16: VUC | D16: 0 | E16: =VLOOKUP($C16,FROTA!$B$58:$G$63,6,0)*D16 -> 0 | F16: 0 | G16: =VLOOKUP($C16,FROTA!$B$58:$G$63,6,0)*F16 -> 0 | H16: 0 | I16: =VLOOKUP($C16,FROTA!$B$58:$G$63,6,0)*H16 -> 0 | J16: 0 | K16: =VLOOKUP($C16,FROTA!$B$58:$G$63,6,0)*J16 -> 0 | L16: 0 | M16: =VLOOKUP($C16,FROTA!$B$58:$G$63,6,0)*L16 -> 0 | N16: 0 | O16: =VLOOKUP($C16,FROTA!$B$58:$G$63,6,0)*N16 -> 0
C17: TOCO 3/4 | D17: 0 | E17: =VLOOKUP($C17,FROTA!$B$58:$G$63,6,0)*D17 -> 0 | F17: 0 | G17: =VLOOKUP($C17,FROTA!$B$58:$G$63,6,0)*F17 -> 0 | H17: 0 | I17: =VLOOKUP($C17,FROTA!$B$58:$G$63,6,0)*H17 -> 0 | J17: 0 | K17: =VLOOKUP($C17,FROTA!$B$58:$G$63,6,0)*J17 -> 0 | L17: 0 | M17: =VLOOKUP($C17,FROTA!$B$58:$G$63,6,0)*L17 -> 0 | N17: 0 | O17: =VLOOKUP($C17,FROTA!$B$58:$G$63,6,0)*N17 -> 0
C18: TOCO | D18: 0 | E18: =VLOOKUP($C18,FROTA!$B$58:$G$63,6,0)*D18 -> 0 | F18: 0 | G18: =VLOOKUP($C18,FROTA!$B$58:$G$63,6,0)*F18 -> 0 | H18: 0 | I18: =VLOOKUP($C18,FROTA!$B$58:$G$63,6,0)*H18 -> 0 | J18: 0 | K18: =VLOOKUP($C18,FROTA!$B$58:$G$63,6,0)*J18 -> 0 | L18: 0 | M18: =VLOOKUP($C18,FROTA!$B$58:$G$63,6,0)*L18 -> 0 | N18: 0 | O18: =VLOOKUP($C18,FROTA!$B$58:$G$63,6,0)*N18 -> 0
C19: TRUCK | D19: 0 | E19: =VLOOKUP($C19,FROTA!$B$58:$G$63,6,0)*D19 -> 0 | F19: 0 | G19: =VLOOKUP($C19,FROTA!$B$58:$G$63,6,0)*F19 -> 0 | H19: 0 | I19: =VLOOKUP($C19,FROTA!$B$58:$G$63,6,0)*H19 -> 0 | J19: 0 | K19: =VLOOKUP($C19,FROTA!$B$58:$G$63,6,0)*J19 -> 0 | L19: 0 | M19: =VLOOKUP($C19,FROTA!$B$58:$G$63,6,0)*L19 -> 0 | N19: 0 | O19: =VLOOKUP($C19,FROTA!$B$58:$G$63,6,0)*N19 -> 0
C20: CARRETA | D20: 0 | E20: =VLOOKUP($C20,FROTA!$B$58:$G$63,6,0)*D20 -> 0 | F20: 0 | G20: =VLOOKUP($C20,FROTA!$B$58:$G$63,6,0)*F20 -> 0 | H20: 0 | I20: =VLOOKUP($C20,FROTA!$B$58:$G$63,6,0)*H20 -> 0 | J20: 0 | K20: =VLOOKUP($C20,FROTA!$B$58:$G$63,6,0)*J20 -> 0 | L20: 0 | M20: =VLOOKUP($C20,FROTA!$B$58:$G$63,6,0)*L20 -> 0 | N20: 0 | O20: =VLOOKUP($C20,FROTA!$B$58:$G$63,6,0)*N20 -> 0
B21: EMBALAGEM/APANHA/ENTREGA | C21: HR | D21: 0 | E21: =VLOOKUP($C21,FROTA!$B$58:$G$63,6,0)*D21 -> 0 | F21: 0 | G21: =VLOOKUP($C21,FROTA!$B$58:$G$63,6,0)*F21 -> 0 | H21: 0 | I21: =VLOOKUP($C21,FROTA!$B$58:$G$63,6,0)*H21 -> 0 | J21: 0 | K21: =VLOOKUP($C21,FROTA!$B$58:$G$63,6,0)*J21 -> 0 | L21: 0 | M21: =VLOOKUP($C21,FROTA!$B$58:$G$63,6,0)*L21 -> 0 | N21: 0 | O21: =VLOOKUP($C21,FROTA!$B$58:$G$63,6,0)*N21 -> 0
C22: VUC | D22: 0 | E22: =VLOOKUP($C22,FROTA!$B$58:$G$63,6,0)*D22 -> 0 | F22: 0 | G22: =VLOOKUP($C22,FROTA!$B$58:$G$63,6,0)*F22 -> 0 | H22: 0 | I22: =VLOOKUP($C22,FROTA!$B$58:$G$63,6,0)*H22 -> 0 | J22: 0 | K22: =VLOOKUP($C22,FROTA!$B$58:$G$63,6,0)*J22 -> 0 | L22: 0 | M22: =VLOOKUP($C22,FROTA!$B$58:$G$63,6,0)*L22 -> 0 | N22: 0 | O22: =VLOOKUP($C22,FROTA!$B$58:$G$63,6,0)*N22 -> 0
C23: TOCO 3/4 | D23: 1 | E23: =VLOOKUP($C23,FROTA!$B$58:$G$63,6,0)*D23 -> 482.98856 | F23: 0 | G23: =VLOOKUP($C23,FROTA!$B$58:$G$63,6,0)*F23 -> 0 | H23: 0 | I23: =VLOOKUP($C23,FROTA!$B$58:$G$63,6,0)*H23 -> 0 | J23: 0 | K23: =VLOOKUP($C23,FROTA!$B$58:$G$63,6,0)*J23 -> 0 | L23: 0 | M23: =VLOOKUP($C23,FROTA!$B$58:$G$63,6,0)*L23 -> 0 | N23: 0 | O23: =VLOOKUP($C23,FROTA!$B$58:$G$63,6,0)*N23 -> 0
C24: TOCO | D24: 0 | E24: =VLOOKUP($C24,FROTA!$B$58:$G$63,6,0)*D24 -> 0 | F24: 0 | G24: =VLOOKUP($C24,FROTA!$B$58:$G$63,6,0)*F24 -> 0 | H24: 0 | I24: =VLOOKUP($C24,FROTA!$B$58:$G$63,6,0)*H24 -> 0 | J24: 0 | K24: =VLOOKUP($C24,FROTA!$B$58:$G$63,6,0)*J24 -> 0 | L24: 0 | M24: =VLOOKUP($C24,FROTA!$B$58:$G$63,6,0)*L24 -> 0 | N24: 0 | O24: =VLOOKUP($C24,FROTA!$B$58:$G$63,6,0)*N24 -> 0
C25: TRUCK | D25: 0 | E25: =VLOOKUP($C25,FROTA!$B$58:$G$63,6,0)*D25 -> 0 | F25: 0 | G25: =VLOOKUP($C25,FROTA!$B$58:$G$63,6,0)*F25 -> 0 | H25: 0 | I25: =VLOOKUP($C25,FROTA!$B$58:$G$63,6,0)*H25 -> 0 | J25: 0 | K25: =VLOOKUP($C25,FROTA!$B$58:$G$63,6,0)*J25 -> 0 | L25: 0 | M25: =VLOOKUP($C25,FROTA!$B$58:$G$63,6,0)*L25 -> 0 | N25: 0 | O25: =VLOOKUP($C25,FROTA!$B$58:$G$63,6,0)*N25 -> 0
C26: CARRETA | D26: 0 | E26: =VLOOKUP($C26,FROTA!$B$58:$G$63,6,0)*D26 -> 0 | F26: 0 | G26: =VLOOKUP($C26,FROTA!$B$58:$G$63,6,0)*F26 -> 0 | H26: 0 | I26: =VLOOKUP($C26,FROTA!$B$58:$G$63,6,0)*H26 -> 0 | J26: 0 | K26: =VLOOKUP($C26,FROTA!$B$58:$G$63,6,0)*J26 -> 0 | L26: 0 | M26: =VLOOKUP($C26,FROTA!$B$58:$G$63,6,0)*L26 -> 0 | N26: 0 | O26: =VLOOKUP($C26,FROTA!$B$58:$G$63,6,0)*N26 -> 0
B27: APANHA 1 | C27: HR | D27: 0 | E27: =VLOOKUP($C27,FROTA!$B$58:$G$63,6,0)*D27 -> 0 | F27: 0 | G27: =VLOOKUP($C27,FROTA!$B$58:$G$63,6,0)*F27 -> 0 | H27: 0 | I27: =VLOOKUP($C27,FROTA!$B$58:$G$63,6,0)*H27 -> 0 | J27: 0 | K27: =VLOOKUP($C27,FROTA!$B$58:$G$63,6,0)*J27 -> 0 | L27: 0 | M27: =VLOOKUP($C27,FROTA!$B$58:$G$63,6,0)*L27 -> 0 | N27: 0 | O27: =VLOOKUP($C27,FROTA!$B$58:$G$63,6,0)*N27 -> 0
C28: VUC | D28: 0 | E28: =VLOOKUP($C28,FROTA!$B$58:$G$63,6,0)*D28 -> 0 | F28: 0 | G28: =VLOOKUP($C28,FROTA!$B$58:$G$63,6,0)*F28 -> 0 | H28: 0 | I28: =VLOOKUP($C28,FROTA!$B$58:$G$63,6,0)*H28 -> 0 | J28: 0 | K28: =VLOOKUP($C28,FROTA!$B$58:$G$63,6,0)*J28 -> 0 | L28: 0 | M28: =VLOOKUP($C28,FROTA!$B$58:$G$63,6,0)*L28 -> 0 | N28: 0 | O28: =VLOOKUP($C28,FROTA!$B$58:$G$63,6,0)*N28 -> 0
C29: TOCO 3/4 | D29: 0 | E29: =VLOOKUP($C29,FROTA!$B$58:$G$63,6,0)*D29 -> 0 | F29: 0 | G29: =VLOOKUP($C29,FROTA!$B$58:$G$63,6,0)*F29 -> 0 | H29: 0 | I29: =VLOOKUP($C29,FROTA!$B$58:$G$63,6,0)*H29 -> 0 | J29: 0 | K29: =VLOOKUP($C29,FROTA!$B$58:$G$63,6,0)*J29 -> 0 | L29: 0 | M29: =VLOOKUP($C29,FROTA!$B$58:$G$63,6,0)*L29 -> 0 | N29: 0 | O29: =VLOOKUP($C29,FROTA!$B$58:$G$63,6,0)*N29 -> 0
C30: TOCO | D30: 0 | E30: =VLOOKUP($C30,FROTA!$B$58:$G$63,6,0)*D30 -> 0 | F30: 0 | G30: =VLOOKUP($C30,FROTA!$B$58:$G$63,6,0)*F30 -> 0 | H30: 0 | I30: =VLOOKUP($C30,FROTA!$B$58:$G$63,6,0)*H30 -> 0 | J30: 0 | K30: =VLOOKUP($C30,FROTA!$B$58:$G$63,6,0)*J30 -> 0 | L30: 0 | M30: =VLOOKUP($C30,FROTA!$B$58:$G$63,6,0)*L30 -> 0 | N30: 0 | O30: =VLOOKUP($C30,FROTA!$B$58:$G$63,6,0)*N30 -> 0
C31: TRUCK | D31: 0 | E31: =VLOOKUP($C31,FROTA!$B$58:$G$63,6,0)*D31 -> 0 | F31: 0 | G31: =VLOOKUP($C31,FROTA!$B$58:$G$63,6,0)*F31 -> 0 | H31: 0 | I31: =VLOOKUP($C31,FROTA!$B$58:$G$63,6,0)*H31 -> 0 | J31: 0 | K31: =VLOOKUP($C31,FROTA!$B$58:$G$63,6,0)*J31 -> 0 | L31: 0 | M31: =VLOOKUP($C31,FROTA!$B$58:$G$63,6,0)*L31 -> 0 | N31: 0 | O31: =VLOOKUP($C31,FROTA!$B$58:$G$63,6,0)*N31 -> 0
C32: CARRETA | D32: 0 | E32: =VLOOKUP($C32,FROTA!$B$58:$G$63,6,0)*D32 -> 0 | F32: 0 | G32: =VLOOKUP($C32,FROTA!$B$58:$G$63,6,0)*F32 -> 0 | H32: 0 | I32: =VLOOKUP($C32,FROTA!$B$58:$G$63,6,0)*H32 -> 0 | J32: 0 | K32: =VLOOKUP($C32,FROTA!$B$58:$G$63,6,0)*J32 -> 0 | L32: 0 | M32: =VLOOKUP($C32,FROTA!$B$58:$G$63,6,0)*L32 -> 0 | N32: 0 | O32: =VLOOKUP($C32,FROTA!$B$58:$G$63,6,0)*N32 -> 0
B33: APANHA 2 | C33: HR | D33: 0 | E33: =VLOOKUP($C33,FROTA!$B$58:$G$63,6,0)*D33 -> 0 | F33: 0 | G33: =VLOOKUP($C33,FROTA!$B$58:$G$63,6,0)*F33 -> 0 | H33: 0 | I33: =VLOOKUP($C33,FROTA!$B$58:$G$63,6,0)*H33 -> 0 | J33: 0 | K33: =VLOOKUP($C33,FROTA!$B$58:$G$63,6,0)*J33 -> 0 | L33: 0 | M33: =VLOOKUP($C33,FROTA!$B$58:$G$63,6,0)*L33 -> 0 | N33: 0 | O33: =VLOOKUP($C33,FROTA!$B$58:$G$63,6,0)*N33 -> 0
